Workbook

Sheet CALENDARIO
A1: Jogo | B1: Data | C1: Hora | D1: Time 1 | E1: Placar 1 | F1: x | G1: Placar 2 | H1: Time 2 | I1: Grupo | J1: Rodada | K1: DataHora
A2: 1 | B2: 46184 | C2: 0.66666667 | D2: México | F2: x | H2: África do Sul | I2: Grupo A | J2: 1ª rodada | K2: =B2+C2 -> 46184.667
A3: 2 | B3: 46184 | C3: 0.95833333 | D3: República da Coreia | F3: x | H3: República Tcheca | I3: Grupo A | J3: 1ª rodada | K3: =B3+C3 -> 46184.958
A4: 3 | B4: 46185 | C4: 0.66666667 | D4: Canadá | F4: x | H4: Bósnia e Herzegovina | I4: Grupo B | J4: 1ª rodada | K4: =B4+C4 -> 46185.667
A5: 4 | B5: 46185 | C5: 0.91666667 | D5: Estados Unidos | F5: x | H5: Paraguai | I5: Grupo D | J5: 1ª rodada | K5: =B5+C5 -> 46185.917
A6: 5 | B6: 46186 | C6: 0.66666667 | D6: Catar | F6: x | H6: Suíça | I6: Grupo B | J6: 1ª rodada | K6: =B6+C6 -> 46186.667
A7: 6 | B7: 46186 | C7: 0.79166667 | D7: Brasil | F7: x | H7: Marrocos | I7: Grupo C | J7: 1ª rodada | K7: =B7+C7 -> 46186.792
A8: 7 | B8: 46186 | C8: 0.91666667 | D8: Haiti | F8: x | H8: Escócia | I8: Grupo C | J8: 1ª rodada | K8: =B8+C8 -> 46186.917
A9: 8 | B9: 46187 | C9: 0.041666667 | D9: Austrália | F9: x | H9: Turquia | I9: Grupo D | J9: 1ª rodada | K9: =B9+C9 -> 46187.042
A10: 9 | B10: 46187 | C10: 0.58333333 | D10: Alemanha | F10: x | H10: Curaçau | I10: Grupo E | J10: 1ª rodada | K10: =B10+C10 -> 46187.583
A11: 10 | B11: 46187 | C11: 0.83333333 | D11: Costa do Marfim | F11: x | H11: Equador | I11: Grupo E | J11: 1ª rodada | K11: =B11+C11 -> 46187.833
A12: 11 | B12: 46187 | C12: 0.70833333 | D12: Holanda | F12: x | H12: Japão | I12: Grupo F | J12: 1ª rodada | K12: =B12+C12 -> 46187.708
A13: 12 | B13: 46187 | C13: 0.95833333 | D13: Suécia | F13: x | H13: Tunísia | I13: Grupo F | J13: 1ª rodada | K13: =B13+C13 -> 46187.958
... A105: 104 | B105: 46222 | C105: 0.66666667 | D105: Vencedor jogo 101 | F105: x | H105: Vencedor jogo 102 | I105: N/A | J105: Final | K105: =B105+C105 -> 46222.667

Sheet ENGLISH
A1: Jogo | B1: Data | C1: Hora | D1: Time 1 | E1: Placar 1 | F1: x | G1: Placar 2 | H1: Time 2 | I1: Grupo | J1: Rodada | K1: DataHora
A2: 1 | B2: 46184 | C2: 0.66666667 | D2: Mexico | F2: x | H2: South Africa | I2: Grupo A | J2: 1ª rodada | K2: =B2+C2 -> 46184.667
A3: 2 | B3: 46184 | C3: 0.95833333 | D3: South Korea | F3: x | H3: Czechia | I3: Grupo A | J3: 1ª rodada | K3: =B3+C3 -> 46184.958
A4: 3 | B4: 46185 | C4: 0.66666667 | D4: Canada | F4: x | H4: Bosnia & Herzegovina | I4: Grupo B | J4: 1ª rodada | K4: =B4+C4 -> 46185.667
A5: 4 | B5: 46185 | C5: 0.91666667 | D5: United States | F5: x | H5: Paraguay | I5: Grupo D | J5: 1ª rodada | K5: =B5+C5 -> 46185.917
A6: 5 | B6: 46186 | C6: 0.66666667 | D6: Qatar | F6: x | H6: Switzerland | I6: Grupo B | J6: 1ª rodada | K6: =B6+C6 -> 46186.667
A7: 6 | B7: 46186 | C7: 0.79166667 | D7: Brazil | F7: x | H7: Morocco | I7: Grupo C | J7: 1ª rodada | K7: =B7+C7 -> 46186.792
A8: 7 | B8: 46186 | C8: 0.91666667 | D8: Haiti | F8: x | H8: Scotland | I8: Grupo C | J8: 1ª rodada | K8: =B8+C8 -> 46186.917
A9: 8 | B9: 46187 | C9: 0.041666667 | D9: Australia | F9: x | H9: Turkey | I9: Grupo D | J9: 1ª rodada | K9: =B9+C9 -> 46187.042
A10: 9 | B10: 46187 | C10: 0.58333333 | D10: Germany | F10: x | H10: Curaçao | I10: Grupo E | J10: 1ª rodada | K10: =B10+C10 -> 46187.583
A11: 10 | B11: 46187 | C11: 0.83333333 | D11: Ivory Coast | F11: x | H11: Ecuador | I11: Grupo E | J11: 1ª rodada | K11: =B11+C11 -> 46187.833
A12: 11 | B12: 46187 | C12: 0.70833333 | D12: Netherlands | F12: x | H12: Japan | I12: Grupo F | J12: 1ª rodada | K12: =B12+C12 -> 46187.708
A13: 12 | B13: 46187 | C13: 0.95833333 | D13: Sweden | F13: x | H13: Tunisia | I13: Grupo F | J13: 1ª rodada | K13: =B13+C13 -> 46187.958
... A73: 72 | B73: 46200 | C73: 0.95833333 | D73: Jordan | F73: x | H73: Argentina | I73: Grupo J | J73: 3ª rodada | K73: =B73+C73 -> 46200.958
A74: 73 | B74: 46201 | C74: A definir | D74: Runner-up Group A | F74: x | H74: Runner-up Group B | I74: N/A | J74: fase de 32-avos
A75: 74 | B75: 46202 | C75: A definir | D75: Winner Group E | F75: x | H75: Third-placed Groups A/B/C/D/F | I75: N/A | J75: fase de 32-avos
A76: 75 | B76: 46202 | C76: A definir | D76: Winner Group F | F76: x | H76: Runner-up Group C | I76: N/A | J76: fase de 32-avos
A77: 76 | B77: 46202 | C77: A definir | D77: Winner Group C | F77: x | H77: Runner-up Group F | I77: N/A | J77: fase de 32-avos
A78: 77 | B78: 46203 | C78: A definir | D78: Winner Group I | F78: x | H78: Third-placed Groups C/D/F/G/H | I78: N/A | J78: fase de 32-avos
A79: 78 | B79: 46203 | C79: A definir | D79: Runner-up Group E | F79: x | H79: Runner-up Group I | I79: N/A | J79: fase de 32-avos
A80: 79 | B80: 46203 | C80: A definir | D80: Winner Group A | F80: x | H80: Third-placed Groups C/E/F/H/I | I80: N/A | J80: fase de 32-avos
A81: 80 | B81: 46204 | C81: A definir | D81: Winner Group L | F81: x | H81: Third-placed Groups E/H/I/J/K | I81: N/A | J81: fase de 32-avos
A82: 81 | B82: 46204 | C82: A definir | D82: Winner Group D | F82: x | H82: Third-placed Groups B/E/F/I/J | I82: N/A | J82: fase de 32-avos
A83: 82 | B83: 46204 | C83: A definir | D83: Winner Group G | F83: x | H83: Third-placed Groups A/E/H/I/J | I83: N/A | J83: fase de 32-avos
A84: 83 | B84: 46205 | C84: A definir | D84: Runner-up Group K | F84: x | H84: Runner-up Group L | I84: N/A | J84: fase de 32-avos
A85: 84 | B85: 46205 | C85: A definir | D85: Winner Group H | F85: x | H85: Runner-up Group J | I85: N/A | J85: fase de 32-avos
... A105: 104 | B105: 46222 | C105: A definir | D105: Winner Match 101 | F105: x | H105: Winner Match 102 | I105: N/A | J105: Final

Sheet CONFIG
A1: Nome | B1: Ponto Totais | C1: Placares Exatos | D1: Link | E1: Email
A2: ALICE | B2: =PALPITES!K$106 -> #VALUE! | C2: =PALPITES!L$106 -> 0
A3: ANNE | B3: =PALPITES!O$106 -> 0 | C3: =PALPITES!P$106 -> 0
A4: CARLINHOS | B4: =PALPITES!S$106 -> 0 | C4: =PALPITES!T$106 -> 0
A5: DEDE | B5: =PALPITES!W$106 -> 0 | C5: =PALPITES!X$106 -> 0
A6: ERIKA | B6: =PALPITES!AA$106 -> 0 | C6: =PALPITES!AB$106 -> 0
A7: GUTO | B7: =PALPITES!AE$106 -> 0 | C7: =PALPITES!AF$106 -> 0
A8: HELENA | B8: =PALPITES!AI$106 -> 0 | C8: =PALPITES!AJ$106 -> 0
A9: JULIA | B9: =PALPITES!AM$106 -> 0 | C9: =PALPITES!AN$106 -> 0
A10: KANOO | B10: =PALPITES!AQ$106 -> 0 | C10: =PALPITES!AR$106 -> 0
A11: KATIA | B11: =PALPITES!AU$106 -> 0 | C11: =PALPITES!AV$106 -> 0
A12: RAFA | B12: =PALPITES!AY$106 -> 0 | C12: =PALPITES!AZ$106 -> 0
A13: RAQUEL | B13: =PALPITES!BC$106 -> 0 | C13: =PALPITES!BD$106 -> 0
A14: RENATO | B14: =PALPITES!BG$106 -> 0 | C14: =PALPITES!BH$106 -> 0
A15: ZE | B15: =PALPITES!BK$106 -> 0 | C15: =PALPITES!BL$106 -> 0
A16: TESTE

Sheet PALPITES
A1: =CALENDARIO!A1 -> Jogo | B1: =CALENDARIO!B1 -> Data | C1: =CALENDARIO!C1 -> Hora | D1: =CALENDARIO!D1 -> Time 1 | E1: =CALENDARIO!E1 -> Placar 1 | F1: =CALENDARIO!F1 -> x | G1: =CALENDARIO!G1 -> Placar 2 | H1: =CALENDARIO!H1 -> Time 2 | I1: =CONFIG!A2 -> ALICE | K1: Ptos | L1: Exto | M1: =CONFIG!A3 -> ANNE | O1: Ptos | P1: Exto | Q1: =CONFIG!A4 -> CARLINHOS | S1: Ptos | T1: Exto | U1: =CONFIG!A5 -> DEDE | W1: Ptos | X1: Exto | Y1: =CONFIG!A6 -> ERIKA | AA1: Ptos | AB1: Exto | AC1: =CONFIG!A7 -> GUTO | AE1: Ptos | AF1: Exto | AG1: =CONFIG!A8 -> HELENA | AI1: Ptos | AJ1: Exto | AK1: =CONFIG!A9 -> JULIA | AM1: Ptos | AN1: Exto | AO1: =CONFIG!A10 -> KANOO | AQ1: Ptos | AR1: Exto | AS1: =CONFIG!A11 -> KATIA | AU1: Ptos | AV1: Exto | AW1: =CONFIG!A12 -> RAFA | AY1: Ptos | AZ1: Exto | BA1: =CONFIG!A13 -> RAQUEL | BC1: Ptos | BD1: Exto | BE1: =CONFIG!A14 -> RENATO | BG1: Ptos | BH1: Exto | BI1: =CONFIG!A15 -> ZE | BK1: Ptos | BL1: Exto
A2: =CALENDARIO!A2 -> 1 | B2: =CALENDARIO!B2 -> 46184 | C2: =CALENDARIO!C2 -> 0.66666667 | D2: =CALENDARIO!D2 -> México | E2: =CALENDARIO!E2 -> 0 | F2: =CALENDARIO!F2 -> x | G2: =CALENDARIO!G2 -> 0 | H2: =CALENDARIO!H2 -> África do Sul | I2: =IFERROR(__xludf.DUMMYFUNCTION("IMPORTRANGE(CONFIG!D2, ""JOGOS!E2:E105"")"),"#N/A") -> #N/A | J2: =IFERROR(__xludf.DUMMYFUNCTION("IMPORTRANGE(CONFIG!D2, ""JOGOS!G2:G105"")"),"#N/A") -> #N/A | K2: =IF(OR(I2="", J2=""), 0, IF(OR($E2="", $G2=""), "", (IF(SIGN($E2-$G2)=SIGN(I2-J2), 2, 0) + IF($E2=I2, 1, 0) + IF($G2=J2, 1, 0) + IF(AND($E2=I2, $G2=J2), 1, 0)))) -> #VALUE! | L2: =IF(OR(I2="", J2="", $E2="", $G2=""), 0, IF(AND($E2=I2, $G2=J2), 1, 0)) -> 0 | M2: =IFERROR(__xludf.DUMMYFUNCTION("IMPORTRANGE(CONFIG!D3, ""JOGOS!E2:E105"")"),"") | N2: =IFERROR(__xludf.DUMMYFUNCTION("IMPORTRANGE(CONFIG!D3, ""JOGOS!G2:G105"")"),"") | O2: =IF(OR(M2="", N2=""), 0, IF(OR($E2="", $G2=""), "", (IF(SIGN($E2-$G2)=SIGN(M2-N2), 2, 0) + IF($E2=M2, 1, 0) + IF($G2=N2, 1, 0) + IF(AND($E2=M2, $G2=N2), 1, 0)))) -> 0 | P2: =IF(OR(M2="", N2="", $E2="", $G2=""), 0, IF(AND($E2=M2, $G2=N2), 1, 0)) -> 0 | Q2: =IFERROR(__xludf.DUMMYFUNCTION("IMPORTRANGE(CONFIG!D4, ""JOGOS!E2:E105"")"),"") | R2: =IFERROR(__xludf.DUMMYFUNCTION("IMPORTRANGE(CONFIG!D4, ""JOGOS!G2:G105"")"),"") | S2: =IF(OR(Q2="", R2=""), 0, IF(OR($E2="", $G2=""), "", (IF(SIGN($E2-$G2)=SIGN(Q2-R2), 2, 0) + IF($E2=Q2, 1, 0) + IF($G2=R2, 1, 0) + IF(AND($E2=Q2, $G2=R2), 1, 0)))) -> 0 | T2: =IF(OR(Q2="", R2="", $E2="", $G2=""), 0, IF(AND($E2=Q2, $G2=R2), 1, 0)) -> 0 | U2: =IFERROR(__xludf.DUMMYFUNCTION("IMPORTRANGE(CONFIG!D5, ""JOGOS!E2:E105"")"),"") | V2: =IFERROR(__xludf.DUMMYFUNCTION("IMPORTRANGE(CONFIG!D5, ""JOGOS!G2:G105"")"),"") | W2: =IF(OR(U2="", V2=""), 0, IF(OR($E2="", $G2=""), "", (IF(SIGN($E2-$G2)=SIGN(U2-V2), 2, 0) + IF($E2=U2, 1, 0) + IF($G2=V2, 1, 0) + IF(AND($E2=U2, $G2=V2), 1, 0)))) -> 0 | X2: =IF(OR(U2="", V2="", $E2="", $G2=""), 0, IF(AND($E2=U2, $G2=V2), 1, 0)) -> 0 | AA2: =IF(OR(Y2="", Z2=""), 0, IF(OR($E2="", $G2=""), "", (IF(SIGN($E2-$G2)=SIGN(Y2-Z2), 2, 0) + IF($E2=Y2, 1, 0) + IF($G2=Z2, 1, 0) + IF(AND($E2=Y2, $G2=Z2), 1, 0)))) -> 0 | AB2: =IF(OR(Y2="", Z2="", $E2="", $G2=""), 0, IF(AND($E2=Y2, $G2=Z2), 1, 0)) -> 0 | AC2: =IFERROR(__xludf.DUMMYFUNCTION("IMPORTRANGE(CONFIG!D7, ""JOGOS!E2:E105"")"),"") | AD2: =IFERROR(__xludf.DUMMYFUNCTION("IMPORTRANGE(CONFIG!D7, ""JOGOS!G2:G105"")"),"") | AE2: =IF(OR(AC2="", AD2=""), 0, IF(OR($E2="", $G2=""), "", (IF(SIGN($E2-$G2)=SIGN(AC2-AD2), 2, 0) + IF($E2=AC2, 1, 0) + IF($G2=AD2, 1, 0) + IF(AND($E2=AC2, $G2=AD2), 1, 0)))) -> 0 | AF2: =IF(OR(AC2="", AD2="", $E2="", $G2=""), 0, IF(AND($E2=AC2, $G2=AD2), 1, 0)) -> 0 | AG2: =IFERROR(__xludf.DUMMYFUNCTION("IMPORTRANGE(CONFIG!D8, ""JOGOS!E2:E105"")"),"") | AH2: =IFERROR(__xludf.DUMMYFUNCTION("IMPORTRANGE(CONFIG!D8, ""JOGOS!G2:G105"")"),"") | AI2: =IF(OR(AG2="", AH2=""), 0, IF(OR($E2="", $G2=""), "", (IF(SIGN($E2-$G2)=SIGN(AG2-AH2), 2, 0) + IF($E2=AG2, 1, 0) + IF($G2=AH2, 1, 0) + IF(AND($E2=AG2, $G2=AH2), 1, 0)))) -> 0 | AJ2: =IF(OR(AG2="", AH2="", $E2="", $G2=""), 0, IF(AND($E2=AG2, $G2=AH2), 1, 0)) -> 0 | AK2: =IFERROR(__xludf.DUMMYFUNCTION("IMPORTRANGE(CONFIG!D9, ""JOGOS!E2:E105"")"),"") | AL2: =IFERROR(__xludf.DUMMYFUNCTION("IMPORTRANGE(CONFIG!D9, ""JOGOS!G2:G105"")"),"") | AM2: =IF(OR(AK2="", AL2=""), 0, IF(OR($E2="", $G2=""), "", (IF(SIGN($E2-$G2)=SIGN(AK2-AL2), 2, 0) + IF($E2=AK2, 1, 0) + IF($G2=AL2, 1, 0) + IF(AND($E2=AK2, $G2=AL2), 1, 0)))) -> 0 | AN2: =IF(OR(AK2="", AL2="", $E2="", $G2=""), 0, IF(AND($E2=AK2, $G2=AL2), 1, 0)) -> 0 | AO2: =IFERROR(__xludf.DUMMYFUNCTION("IMPORTRANGE(CONFIG!D10, ""JOGOS!E2:E105"")"),"") | AP2: =IFERROR(__xludf.DUMMYFUNCTION("IMPORTRANGE(CONFIG!D10, ""JOGOS!G2:G105"")"),"") | AQ2: =IF(OR(AO2="", AP2=""), 0, IF(OR($E2="", $G2=""), "", (IF(SIGN($E2-$G2)=SIGN(AO2-AP2), 2, 0) + IF($E2=AO2, 1, 0) + IF($G2=AP2, 1, 0) + IF(AND($E2=AO2, $G2=AP2), 1, 0)))) -> 0 | AR2: =IF(OR(AO2="", AP2="", $E2="", $G2=""), 0, IF(AND($E2=AO2, $G2=AP2), 1, 0)) -> 0 | AS2: =IFERROR(__xludf.DUMMYFUNCTION("IMPORTRANGE(CONFIG!D11, ""JOGOS!E2:E105"")"),"") | AT2: =IFERROR(__xludf.DUMMYFUNCTION("IMPORTRANGE(CONFIG!D11, ""JOGOS!G2:G105"")"),"") | AU2: =IF(OR(AS2="", AT2=""), 0, IF(OR($E2="", $G2=""), "", (IF(SIGN($E2-$G2)=SIGN(AS2-AT2), 2, 0) + IF($E2=AS2, 1, 0) + IF($G2=AT2, 1, 0) + IF(AND($E2=AS2, $G2=AT2), 1, 0)))) -> 0 | AV2: =IF(OR(AS2="", AT2="", $E2="", $G2=""), 0, IF(AND($E2=AS2, $G2=AT2), 1, 0)) -> 0 | AY2: =IF(OR(AW2="", AX2=""), 0, IF(OR($E2="", $G2=""), "", (IF(SIGN($E2-$G2)=SIGN(AW2-AX2), 2, 0) + IF($E2=AW2, 1, 0) + IF($G2=AX2, 1, 0) + IF(AND($E2=AW2, $G2=AX2), 1, 0)))) -> 0 | AZ2: =IF(OR(AW2="", AX2="", $E2="", $G2=""), 0, IF(AND($E2=AW2, $G2=AX2), 1, 0)) -> 0 | BA2: =IFERROR(__xludf.DUMMYFUNCTION("IMPORTRANGE(CONFIG!D13, ""JOGOS!E2:E105"")"),"") | BB2: =IFERROR(__xludf.DUMMYFUNCTION("IMPORTRANGE(CONFIG!D13, ""JOGOS!G2:G105"")"),"") | BC2: =IF(OR(BA2="", BB2=""), 0, IF(OR($E2="", $G2=""), "", (IF(SIGN($E2-$G2)=SIGN(BA2-BB2), 2, 0) + IF($E2=BA2, 1, 0) + IF($G2=BB2, 1, 0) + IF(AND($E2=BA2, $G2=BB2), 1, 0)))) -> 0 | BD2: =IF(OR(BA2="", BB2="", $E2="", $G2=""), 0, IF(AND($E2=BA2, $G2=BB2), 1, 0)) -> 0 | BE2: =IFERROR(__xludf.DUMMYFUNCTION("IMPORTRANGE(CONFIG!D14, ""JOGOS!E2:E105"")"),"") | BF2: =IFERROR(__xludf.DUMMYFUNCTION("IMPORTRANGE(CONFIG!D14, ""JOGOS!G2:G105"")"),"") | BG2: =IF(OR(BE2="", BF2=""), 0, IF(OR($E2="", $G2=""), "", (IF(SIGN($E2-$G2)=SIGN(BE2-BF2), 2, 0) + IF($E2=BE2, 1, 0) + IF($G2=BF2, 1, 0) + IF(AND($E2=BE2, $G2=BF2), 1, 0)))) -> 0 | BH2: =IF(OR(BE2="", BF2="", $E2="", $G2=""), 0, IF(AND($E2=BE2, $G2=BF2), 1, 0)) -> 0 | BI2: =IFERROR(__xludf.DUMMYFUNCTION("IMPORTRANGE(CONFIG!D15, ""JOGOS!E2:E105"")"),"") | BJ2: =IFERROR(__xludf.DUMMYFUNCTION("IMPORTRANGE(CONFIG!D15, ""JOGOS!G2:G105"")"),"") | BK2: =IF(OR(BI2="", BJ2=""), 0, IF(OR($E2="", $G2=""), "", (IF(SIGN($E2-$G2)=SIGN(BI2-BJ2), 2, 0) + IF($E2=BI2, 1, 0) + IF($G2=BJ2, 1, 0) + IF(AND($E2=BI2, $G2=BJ2), 1, 0)))) -> 0 | BL2: =IF(OR(BI2="", BJ2="", $E2="", $G2=""), 0, IF(AND($E2=BI2, $G2=BJ2), 1, 0)) -> 0
A3: =CALENDARIO!A3 -> 2 | B3: =CALENDARIO!B3 -> 46184 | C3: =CALENDARIO!C3 -> 0.95833333 | D3: =CALENDARIO!D3 -> República da Coreia | E3: =CALENDARIO!E3 -> 0 | F3: =CALENDARIO!F3 -> x | G3: =CALENDARIO!G3 -> 0 | H3: =CALENDARIO!H3 -> República Tcheca | K3: =IF(OR(I3="", J3=""), 0, IF(OR($E3="", $G3=""), "", (IF(SIGN($E3-$G3)=SIGN(I3-J3), 2, 0) + IF($E3=I3, 1, 0) + IF($G3=J3, 1, 0) + IF(AND($E3=I3, $G3=J3), 1, 0)))) -> 0 | L3: =IF(OR(I3="", J3="", $E3="", $G3=""), 0, IF(AND($E3=I3, $G3=J3), 1, 0)) -> 0 | O3: =IF(OR(M3="", N3=""), 0, IF(OR($E3="", $G3=""), "", (IF(SIGN($E3-$G3)=SIGN(M3-N3), 2, 0) + IF($E3=M3, 1, 0) + IF($G3=N3, 1, 0) + IF(AND($E3=M3, $G3=N3), 1, 0)))) -> 0 | P3: =IF(OR(M3="", N3="", $E3="", $G3=""), 0, IF(AND($E3=M3, $G3=N3), 1, 0)) -> 0 | S3: =IF(OR(Q3="", R3=""), 0, IF(OR($E3="", $G3=""), "", (IF(SIGN($E3-$G3)=SIGN(Q3-R3), 2, 0) + IF($E3=Q3, 1, 0) + IF($G3=R3, 1, 0) + IF(AND($E3=Q3, $G3=R3), 1, 0)))) -> 0 | T3: =IF(OR(Q3="", R3="", $E3="", $G3=""), 0, IF(AND($E3=Q3, $G3=R3), 1, 0)) -> 0 | W3: =IF(OR(U3="", V3=""), 0, IF(OR($E3="", $G3=""), "", (IF(SIGN($E3-$G3)=SIGN(U3-V3), 2, 0) + IF($E3=U3, 1, 0) + IF($G3=V3, 1, 0) + IF(AND($E3=U3, $G3=V3), 1, 0)))) -> 0 | X3: =IF(OR(U3="", V3="", $E3="", $G3=""), 0, IF(AND($E3=U3, $G3=V3), 1, 0)) -> 0 | AA3: =IF(OR(Y3="", Z3=""), 0, IF(OR($E3="", $G3=""), "", (IF(SIGN($E3-$G3)=SIGN(Y3-Z3), 2, 0) + IF($E3=Y3, 1, 0) + IF($G3=Z3, 1, 0) + IF(AND($E3=Y3, $G3=Z3), 1, 0)))) -> 0 | AB3: =IF(OR(Y3="", Z3="", $E3="", $G3=""), 0, IF(AND($E3=Y3, $G3=Z3), 1, 0)) -> 0 | AE3: =IF(OR(AC3="", AD3=""), 0, IF(OR($E3="", $G3=""), "", (IF(SIGN($E3-$G3)=SIGN(AC3-AD3), 2, 0) + IF($E3=AC3, 1, 0) + IF($G3=AD3, 1, 0) + IF(AND($E3=AC3, $G3=AD3), 1, 0)))) -> 0 | AF3: =IF(OR(AC3="", AD3="", $E3="", $G3=""), 0, IF(AND($E3=AC3, $G3=AD3), 1, 0)) -> 0 | AI3: =IF(OR(AG3="", AH3=""), 0, IF(OR($E3="", $G3=""), "", (IF(SIGN($E3-$G3)=SIGN(AG3-AH3), 2, 0) + IF($E3=AG3, 1, 0) + IF($G3=AH3, 1, 0) + IF(AND($E3=AG3, $G3=AH3), 1, 0)))) -> 0 | AJ3: =IF(OR(AG3="", AH3="", $E3="", $G3=""), 0, IF(AND($E3=AG3, $G3=AH3), 1, 0)) -> 0 | AM3: =IF(OR(AK3="", AL3=""), 0, IF(OR($E3="", $G3=""), "", (IF(SIGN($E3-$G3)=SIGN(AK3-AL3), 2, 0) + IF($E3=AK3, 1, 0) + IF($G3=AL3, 1, 0) + IF(AND($E3=AK3, $G3=AL3), 1, 0)))) -> 0 | AN3: =IF(OR(AK3="", AL3="", $E3="", $G3=""), 0, IF(AND($E3=AK3, $G3=AL3), 1, 0)) -> 0 | AQ3: =IF(OR(AO3="", AP3=""), 0, IF(OR($E3="", $G3=""), "", (IF(SIGN($E3-$G3)=SIGN(AO3-AP3), 2, 0) + IF($E3=AO3, 1, 0) + IF($G3=AP3, 1, 0) + IF(AND($E3=AO3, $G3=AP3), 1, 0)))) -> 0 | AR3: =IF(OR(AO3="", AP3="", $E3="", $G3=""), 0, IF(AND($E3=AO3, $G3=AP3), 1, 0)) -> 0 | AU3: =IF(OR(AS3="", AT3=""), 0, IF(OR($E3="", $G3=""), "", (IF(SIGN($E3-$G3)=SIGN(AS3-AT3), 2, 0) + IF($E3=AS3, 1, 0) + IF($G3=AT3, 1, 0) + IF(AND($E3=AS3, $G3=AT3), 1, 0)))) -> 0 | AV3: =IF(OR(AS3="", AT3="", $E3="", $G3=""), 0, IF(AND($E3=AS3, $G3=AT3), 1, 0)) -> 0 | AY3: =IF(OR(AW3="", AX3=""), 0, IF(OR($E3="", $G3=""), "", (IF(SIGN($E3-$G3)=SIGN(AW3-AX3), 2, 0) + IF($E3=AW3, 1, 0) + IF($G3=AX3, 1, 0) + IF(AND($E3=AW3, $G3=AX3), 1, 0)))) -> 0 | AZ3: =IF(OR(AW3="", AX3="", $E3="", $G3=""), 0, IF(AND($E3=AW3, $G3=AX3), 1, 0)) -> 0 | BC3: =IF(OR(BA3="", BB3=""), 0, IF(OR($E3="", $G3=""), "", (IF(SIGN($E3-$G3)=SIGN(BA3-BB3), 2, 0) + IF($E3=BA3, 1, 0) + IF($G3=BB3, 1, 0) + IF(AND($E3=BA3, $G3=BB3), 1, 0)))) -> 0 | BD3: =IF(OR(BA3="", BB3="", $E3="", $G3=""), 0, IF(AND($E3=BA3, $G3=BB3), 1, 0)) -> 0 | BG3: =IF(OR(BE3="", BF3=""), 0, IF(OR($E3="", $G3=""), "", (IF(SIGN($E3-$G3)=SIGN(BE3-BF3), 2, 0) + IF($E3=BE3, 1, 0) + IF($G3=BF3, 1, 0) + IF(AND($E3=BE3, $G3=BF3), 1, 0)))) -> 0 | BH3: =IF(OR(BE3="", BF3="", $E3="", $G3=""), 0, IF(AND($E3=BE3, $G3=BF3), 1, 0)) -> 0 | BK3: =IF(OR(BI3="", BJ3=""), 0, IF(OR($E3="", $G3=""), "", (IF(SIGN($E3-$G3)=SIGN(BI3-BJ3), 2, 0) + IF($E3=BI3, 1, 0) + IF($G3=BJ3, 1, 0) + IF(AND($E3=BI3, $G3=BJ3), 1, 0)))) -> 0 | BL3: =IF(OR(BI3="", BJ3="", $E3="", $G3=""), 0, IF(AND($E3=BI3, $G3=BJ3), 1, 0)) -> 0
A4: =CALENDARIO!A4 -> 3 | B4: =CALENDARIO!B4 -> 46185 | C4: =CALENDARIO!C4 -> 0.66666667 | D4: =CALENDARIO!D4 -> Canadá | E4: =CALENDARIO!E4 -> 0 | F4: =CALENDARIO!F4 -> x | G4: =CALENDARIO!G4 -> 0 | H4: =CALENDARIO!H4 -> Bósnia e Herzegovina | K4: =IF(OR(I4="", J4=""), 0, IF(OR($E4="", $G4=""), "", (IF(SIGN($E4-$G4)=SIGN(I4-J4), 2, 0) + IF($E4=I4, 1, 0) + IF($G4=J4, 1, 0) + IF(AND($E4=I4, $G4=J4), 1, 0)))) -> 0 | L4: =IF(OR(I4="", J4="", $E4="", $G4=""), 0, IF(AND($E4=I4, $G4=J4), 1, 0)) -> 0 | O4: =IF(OR(M4="", N4=""), 0, IF(OR($E4="", $G4=""), "", (IF(SIGN($E4-$G4)=SIGN(M4-N4), 2, 0) + IF($E4=M4, 1, 0) + IF($G4=N4, 1, 0) + IF(AND($E4=M4, $G4=N4), 1, 0)))) -> 0 | P4: =IF(OR(M4="", N4="", $E4="", $G4=""), 0, IF(AND($E4=M4, $G4=N4), 1, 0)) -> 0 | S4: =IF(OR(Q4="", R4=""), 0, IF(OR($E4="", $G4=""), "", (IF(SIGN($E4-$G4)=SIGN(Q4-R4), 2, 0) + IF($E4=Q4, 1, 0) + IF($G4=R4, 1, 0) + IF(AND($E4=Q4, $G4=R4), 1, 0)))) -> 0 | T4: =IF(OR(Q4="", R4="", $E4="", $G4=""), 0, IF(AND($E4=Q4, $G4=R4), 1, 0)) -> 0 | W4: =IF(OR(U4="", V4=""), 0, IF(OR($E4="", $G4=""), "", (IF(SIGN($E4-$G4)=SIGN(U4-V4), 2, 0) + IF($E4=U4, 1, 0) + IF($G4=V4, 1, 0) + IF(AND($E4=U4, $G4=V4), 1, 0)))) -> 0 | X4: =IF(OR(U4="", V4="", $E4="", $G4=""), 0, IF(AND($E4=U4, $G4=V4), 1, 0)) -> 0 | AA4: =IF(OR(Y4="", Z4=""), 0, IF(OR($E4="", $G4=""), "", (IF(SIGN($E4-$G4)=SIGN(Y4-Z4), 2, 0) + IF($E4=Y4, 1, 0) + IF($G4=Z4, 1, 0) + IF(AND($E4=Y4, $G4=Z4), 1, 0)))) -> 0 | AB4: =IF(OR(Y4="", Z4="", $E4="", $G4=""), 0, IF(AND($E4=Y4, $G4=Z4), 1, 0)) -> 0 | AE4: =IF(OR(AC4="", AD4=""), 0, IF(OR($E4="", $G4=""), "", (IF(SIGN($E4-$G4)=SIGN(AC4-AD4), 2, 0) + IF($E4=AC4, 1, 0) + IF($G4=AD4, 1, 0) + IF(AND($E4=AC4, $G4=AD4), 1, 0)))) -> 0 | AF4: =IF(OR(AC4="", AD4="", $E4="", $G4=""), 0, IF(AND($E4=AC4, $G4=AD4), 1, 0)) -> 0 | AI4: =IF(OR(AG4="", AH4=""), 0, IF(OR($E4="", $G4=""), "", (IF(SIGN($E4-$G4)=SIGN(AG4-AH4), 2, 0) + IF($E4=AG4, 1, 0) + IF($G4=AH4, 1, 0) + IF(AND($E4=AG4, $G4=AH4), 1, 0)))) -> 0 | AJ4: =IF(OR(AG4="", AH4="", $E4="", $G4=""), 0, IF(AND($E4=AG4, $G4=AH4), 1, 0)) -> 0 | AM4: =IF(OR(AK4="", AL4=""), 0, IF(OR($E4="", $G4=""), "", (IF(SIGN($E4-$G4)=SIGN(AK4-AL4), 2, 0) + IF($E4=AK4, 1, 0) + IF($G4=AL4, 1, 0) + IF(AND($E4=AK4, $G4=AL4), 1, 0)))) -> 0 | AN4: =IF(OR(AK4="", AL4="", $E4="", $G4=""), 0, IF(AND($E4=AK4, $G4=AL4), 1, 0)) -> 0 | AQ4: =IF(OR(AO4="", AP4=""), 0, IF(OR($E4="", $G4=""), "", (IF(SIGN($E4-$G4)=SIGN(AO4-AP4), 2, 0) + IF($E4=AO4, 1, 0) + IF($G4=AP4, 1, 0) + IF(AND($E4=AO4, $G4=AP4), 1, 0)))) -> 0 | AR4: =IF(OR(AO4="", AP4="", $E4="", $G4=""), 0, IF(AND($E4=AO4, $G4=AP4), 1, 0)) -> 0 | AU4: =IF(OR(AS4="", AT4=""), 0, IF(OR($E4="", $G4=""), "", (IF(SIGN($E4-$G4)=SIGN(AS4-AT4), 2, 0) + IF($E4=AS4, 1, 0) + IF($G4=AT4, 1, 0) + IF(AND($E4=AS4, $G4=AT4), 1, 0)))) -> 0 | AV4: =IF(OR(AS4="", AT4="", $E4="", $G4=""), 0, IF(AND($E4=AS4, $G4=AT4), 1, 0)) -> 0 | AY4: =IF(OR(AW4="", AX4=""), 0, IF(OR($E4="", $G4=""), "", (IF(SIGN($E4-$G4)=SIGN(AW4-AX4), 2, 0) + IF($E4=AW4, 1, 0) + IF($G4=AX4, 1, 0) + IF(AND($E4=AW4, $G4=AX4), 1, 0)))) -> 0 | AZ4: =IF(OR(AW4="", AX4="", $E4="", $G4=""), 0, IF(AND($E4=AW4, $G4=AX4), 1, 0)) -> 0 | BC4: =IF(OR(BA4="", BB4=""), 0, IF(OR($E4="", $G4=""), "", (IF(SIGN($E4-$G4)=SIGN(BA4-BB4), 2, 0) + IF($E4=BA4, 1, 0) + IF($G4=BB4, 1, 0) + IF(AND($E4=BA4, $G4=BB4), 1, 0)))) -> 0 | BD4: =IF(OR(BA4="", BB4="", $E4="", $G4=""), 0, IF(AND($E4=BA4, $G4=BB4), 1, 0)) -> 0 | BG4: =IF(OR(BE4="", BF4=""), 0, IF(OR($E4="", $G4=""), "", (IF(SIGN($E4-$G4)=SIGN(BE4-BF4), 2, 0) + IF($E4=BE4, 1, 0) + IF($G4=BF4, 1, 0) + IF(AND($E4=BE4, $G4=BF4), 1, 0)))) -> 0 | BH4: =IF(OR(BE4="", BF4="", $E4="", $G4=""), 0, IF(AND($E4=BE4, $G4=BF4), 1, 0)) -> 0 | BK4: =IF(OR(BI4="", BJ4=""), 0, IF(OR($E4="", $G4=""), "", (IF(SIGN($E4-$G4)=SIGN(BI4-BJ4), 2, 0) + IF($E4=BI4, 1, 0) + IF($G4=BJ4, 1, 0) + IF(AND($E4=BI4, $G4=BJ4), 1, 0)))) -> 0 | BL4: =IF(OR(BI4="", BJ4="", $E4="", $G4=""), 0, IF(AND($E4=BI4, $G4=BJ4), 1, 0)) -> 0
A5: =CALENDARIO!A5 -> 4 | B5: =CALENDARIO!B5 -> 46185 | C5: =CALENDARIO!C5 -> 0.91666667 | D5: =CALENDARIO!D5 -> Estados Unidos | E5: =CALENDARIO!E5 -> 0 | F5: =CALENDARIO!F5 -> x | G5: =CALENDARIO!G5 -> 0 | H5: =CALENDARIO!H5 -> Paraguai | K5: =IF(OR(I5="", J5=""), 0, IF(OR($E5="", $G5=""), "", (IF(SIGN($E5-$G5)=SIGN(I5-J5), 2, 0) + IF($E5=I5, 1, 0) + IF($G5=J5, 1, 0) + IF(AND($E5=I5, $G5=J5), 1, 0)))) -> 0 | L5: =IF(OR(I5="", J5="", $E5="", $G5=""), 0, IF(AND($E5=I5, $G5=J5), 1, 0)) -> 0 | O5: =IF(OR(M5="", N5=""), 0, IF(OR($E5="", $G5=""), "", (IF(SIGN($E5-$G5)=SIGN(M5-N5), 2, 0) + IF($E5=M5, 1, 0) + IF($G5=N5, 1, 0) + IF(AND($E5=M5, $G5=N5), 1, 0)))) -> 0 | P5: =IF(OR(M5="", N5="", $E5="", $G5=""), 0, IF(AND($E5=M5, $G5=N5), 1, 0)) -> 0 | S5: =IF(OR(Q5="", R5=""), 0, IF(OR($E5="", $G5=""), "", (IF(SIGN($E5-$G5)=SIGN(Q5-R5), 2, 0) + IF($E5=Q5, 1, 0) + IF($G5=R5, 1, 0) + IF(AND($E5=Q5, $G5=R5), 1, 0)))) -> 0 | T5: =IF(OR(Q5="", R5="", $E5="", $G5=""), 0, IF(AND($E5=Q5, $G5=R5), 1, 0)) -> 0 | W5: =IF(OR(U5="", V5=""), 0, IF(OR($E5="", $G5=""), "", (IF(SIGN($E5-$G5)=SIGN(U5-V5), 2, 0) + IF($E5=U5, 1, 0) + IF($G5=V5, 1, 0) + IF(AND($E5=U5, $G5=V5), 1, 0)))) -> 0 | X5: =IF(OR(U5="", V5="", $E5="", $G5=""), 0, IF(AND($E5=U5, $G5=V5), 1, 0)) -> 0 | AA5: =IF(OR(Y5="", Z5=""), 0, IF(OR($E5="", $G5=""), "", (IF(SIGN($E5-$G5)=SIGN(Y5-Z5), 2, 0) + IF($E5=Y5, 1, 0) + IF($G5=Z5, 1, 0) + IF(AND($E5=Y5, $G5=Z5), 1, 0)))) -> 0 | AB5: =IF(OR(Y5="", Z5="", $E5="", $G5=""), 0, IF(AND($E5=Y5, $G5=Z5), 1, 0)) -> 0 | AE5: =IF(OR(AC5="", AD5=""), 0, IF(OR($E5="", $G5=""), "", (IF(SIGN($E5-$G5)=SIGN(AC5-AD5), 2, 0) + IF($E5=AC5, 1, 0) + IF($G5=AD5, 1, 0) + IF(AND($E5=AC5, $G5=AD5), 1, 0)))) -> 0 | AF5: =IF(OR(AC5="", AD5="", $E5="", $G5=""), 0, IF(AND($E5=AC5, $G5=AD5), 1, 0)) -> 0 | AI5: =IF(OR(AG5="", AH5=""), 0, IF(OR($E5="", $G5=""), "", (IF(SIGN($E5-$G5)=SIGN(AG5-AH5), 2, 0) + IF($E5=AG5, 1, 0) + IF($G5=AH5, 1, 0) + IF(AND($E5=AG5, $G5=AH5), 1, 0)))) -> 0 | AJ5: =IF(OR(AG5="", AH5="", $E5="", $G5=""), 0, IF(AND($E5=AG5, $G5=AH5), 1, 0)) -> 0 | AM5: =IF(OR(AK5="", AL5=""), 0, IF(OR($E5="", $G5=""), "", (IF(SIGN($E5-$G5)=SIGN(AK5-AL5), 2, 0) + IF($E5=AK5, 1, 0) + IF($G5=AL5, 1, 0) + IF(AND($E5=AK5, $G5=AL5), 1, 0)))) -> 0 | AN5: =IF(OR(AK5="", AL5="", $E5="", $G5=""), 0, IF(AND($E5=AK5, $G5=AL5), 1, 0)) -> 0 | AQ5: =IF(OR(AO5="", AP5=""), 0, IF(OR($E5="", $G5=""), "", (IF(SIGN($E5-$G5)=SIGN(AO5-AP5), 2, 0) + IF($E5=AO5, 1, 0) + IF($G5=AP5, 1, 0) + IF(AND($E5=AO5, $G5=AP5), 1, 0)))) -> 0 | AR5: =IF(OR(AO5="", AP5="", $E5="", $G5=""), 0, IF(AND($E5=AO5, $G5=AP5), 1, 0)) -> 0 | AU5: =IF(OR(AS5="", AT5=""), 0, IF(OR($E5="", $G5=""), "", (IF(SIGN($E5-$G5)=SIGN(AS5-AT5), 2, 0) + IF($E5=AS5, 1, 0) + IF($G5=AT5, 1, 0) + IF(AND($E5=AS5, $G5=AT5), 1, 0)))) -> 0 | AV5: =IF(OR(AS5="", AT5="", $E5="", $G5=""), 0, IF(AND($E5=AS5, $G5=AT5), 1, 0)) -> 0 | AY5: =IF(OR(AW5="", AX5=""), 0, IF(OR($E5="", $G5=""), "", (IF(SIGN($E5-$G5)=SIGN(AW5-AX5), 2, 0) + IF($E5=AW5, 1, 0) + IF($G5=AX5, 1, 0) + IF(AND($E5=AW5, $G5=AX5), 1, 0)))) -> 0 | AZ5: =IF(OR(AW5="", AX5="", $E5="", $G5=""), 0, IF(AND($E5=AW5, $G5=AX5), 1, 0)) -> 0 | BC5: =IF(OR(BA5="", BB5=""), 0, IF(OR($E5="", $G5=""), "", (IF(SIGN($E5-$G5)=SIGN(BA5-BB5), 2, 0) + IF($E5=BA5, 1, 0) + IF($G5=BB5, 1, 0) + IF(AND($E5=BA5, $G5=BB5), 1, 0)))) -> 0 | BD5: =IF(OR(BA5="", BB5="", $E5="", $G5=""), 0, IF(AND($E5=BA5, $G5=BB5), 1, 0)) -> 0 | BG5: =IF(OR(BE5="", BF5=""), 0, IF(OR($E5="", $G5=""), "", (IF(SIGN($E5-$G5)=SIGN(BE5-BF5), 2, 0) + IF($E5=BE5, 1, 0) + IF($G5=BF5, 1, 0) + IF(AND($E5=BE5, $G5=BF5), 1, 0)))) -> 0 | BH5: =IF(OR(BE5="", BF5="", $E5="", $G5=""), 0, IF(AND($E5=BE5, $G5=BF5), 1, 0)) -> 0 | BK5: =IF(OR(BI5="", BJ5=""), 0, IF(OR($E5="", $G5=""), "", (IF(SIGN($E5-$G5)=SIGN(BI5-BJ5), 2, 0) + IF($E5=BI5, 1, 0) + IF($G5=BJ5, 1, 0) + IF(AND($E5=BI5, $G5=BJ5), 1, 0)))) -> 0 | BL5: =IF(OR(BI5="", BJ5="", $E5="", $G5=""), 0, IF(AND($E5=BI5, $G5=BJ5), 1, 0)) -> 0
A6: =CALENDARIO!A6 -> 5 | B6: =CALENDARIO!B6 -> 46186 | C6: =CALENDARIO!C6 -> 0.66666667 | D6: =CALENDARIO!D6 -> Catar | E6: =CALENDARIO!E6 -> 0 | F6: =CALENDARIO!F6 -> x | G6: =CALENDARIO!G6 -> 0 | H6: =CALENDARIO!H6 -> Suíça | K6: =IF(OR(I6="", J6=""), 0, IF(OR($E6="", $G6=""), "", (IF(SIGN($E6-$G6)=SIGN(I6-J6), 2, 0) + IF($E6=I6, 1, 0) + IF($G6=J6, 1, 0) + IF(AND($E6=I6, $G6=J6), 1, 0)))) -> 0 | L6: =IF(OR(I6="", J6="", $E6="", $G6=""), 0, IF(AND($E6=I6, $G6=J6), 1, 0)) -> 0 | O6: =IF(OR(M6="", N6=""), 0, IF(OR($E6="", $G6=""), "", (IF(SIGN($E6-$G6)=SIGN(M6-N6), 2, 0) + IF($E6=M6, 1, 0) + IF($G6=N6, 1, 0) + IF(AND($E6=M6, $G6=N6), 1, 0)))) -> 0 | P6: =IF(OR(M6="", N6="", $E6="", $G6=""), 0, IF(AND($E6=M6, $G6=N6), 1, 0)) -> 0 | S6: =IF(OR(Q6="", R6=""), 0, IF(OR($E6="", $G6=""), "", (IF(SIGN($E6-$G6)=SIGN(Q6-R6), 2, 0) + IF($E6=Q6, 1, 0) + IF($G6=R6, 1, 0) + IF(AND($E6=Q6, $G6=R6), 1, 0)))) -> 0 | T6: =IF(OR(Q6="", R6="", $E6="", $G6=""), 0, IF(AND($E6=Q6, $G6=R6), 1, 0)) -> 0 | W6: =IF(OR(U6="", V6=""), 0, IF(OR($E6="", $G6=""), "", (IF(SIGN($E6-$G6)=SIGN(U6-V6), 2, 0) + IF($E6=U6, 1, 0) + IF($G6=V6, 1, 0) + IF(AND($E6=U6, $G6=V6), 1, 0)))) -> 0 | X6: =IF(OR(U6="", V6="", $E6="", $G6=""), 0, IF(AND($E6=U6, $G6=V6), 1, 0)) -> 0 | AA6: =IF(OR(Y6="", Z6=""), 0, IF(OR($E6="", $G6=""), "", (IF(SIGN($E6-$G6)=SIGN(Y6-Z6), 2, 0) + IF($E6=Y6, 1, 0) + IF($G6=Z6, 1, 0) + IF(AND($E6=Y6, $G6=Z6), 1, 0)))) -> 0 | AB6: =IF(OR(Y6="", Z6="", $E6="", $G6=""), 0, IF(AND($E6=Y6, $G6=Z6), 1, 0)) -> 0 | AE6: =IF(OR(AC6="", AD6=""), 0, IF(OR($E6="", $G6=""), "", (IF(SIGN($E6-$G6)=SIGN(AC6-AD6), 2, 0) + IF($E6=AC6, 1, 0) + IF($G6=AD6, 1, 0) + IF(AND($E6=AC6, $G6=AD6), 1, 0)))) -> 0 | AF6: =IF(OR(AC6="", AD6="", $E6="", $G6=""), 0, IF(AND($E6=AC6, $G6=AD6), 1, 0)) -> 0 | AI6: =IF(OR(AG6="", AH6=""), 0, IF(OR($E6="", $G6=""), "", (IF(SIGN($E6-$G6)=SIGN(AG6-AH6), 2, 0) + IF($E6=AG6, 1, 0) + IF($G6=AH6, 1, 0) + IF(AND($E6=AG6, $G6=AH6), 1, 0)))) -> 0 | AJ6: =IF(OR(AG6="", AH6="", $E6="", $G6=""), 0, IF(AND($E6=AG6, $G6=AH6), 1, 0)) -> 0 | AM6: =IF(OR(AK6="", AL6=""), 0, IF(OR($E6="", $G6=""), "", (IF(SIGN($E6-$G6)=SIGN(AK6-AL6), 2, 0) + IF($E6=AK6, 1, 0) + IF($G6=AL6, 1, 0) + IF(AND($E6=AK6, $G6=AL6), 1, 0)))) -> 0 | AN6: =IF(OR(AK6="", AL6="", $E6="", $G6=""), 0, IF(AND($E6=AK6, $G6=AL6), 1, 0)) -> 0 | AQ6: =IF(OR(AO6="", AP6=""), 0, IF(OR($E6="", $G6=""), "", (IF(SIGN($E6-$G6)=SIGN(AO6-AP6), 2, 0) + IF($E6=AO6, 1, 0) + IF($G6=AP6, 1, 0) + IF(AND($E6=AO6, $G6=AP6), 1, 0)))) -> 0 | AR6: =IF(OR(AO6="", AP6="", $E6="", $G6=""), 0, IF(AND($E6=AO6, $G6=AP6), 1, 0)) -> 0 | AU6: =IF(OR(AS6="", AT6=""), 0, IF(OR($E6="", $G6=""), "", (IF(SIGN($E6-$G6)=SIGN(AS6-AT6), 2, 0) + IF($E6=AS6, 1, 0) + IF($G6=AT6, 1, 0) + IF(AND($E6=AS6, $G6=AT6), 1, 0)))) -> 0 | AV6: =IF(OR(AS6="", AT6="", $E6="", $G6=""), 0, IF(AND($E6=AS6, $G6=AT6), 1, 0)) -> 0 | AY6: =IF(OR(AW6="", AX6=""), 0, IF(OR($E6="", $G6=""), "", (IF(SIGN($E6-$G6)=SIGN(AW6-AX6), 2, 0) + IF($E6=AW6, 1, 0) + IF($G6=AX6, 1, 0) + IF(AND($E6=AW6, $G6=AX6), 1, 0)))) -> 0 | AZ6: =IF(OR(AW6="", AX6="", $E6="", $G6=""), 0, IF(AND($E6=AW6, $G6=AX6), 1, 0)) -> 0 | BC6: =IF(OR(BA6="", BB6=""), 0, IF(OR($E6="", $G6=""), "", (IF(SIGN($E6-$G6)=SIGN(BA6-BB6), 2, 0) + IF($E6=BA6, 1, 0) + IF($G6=BB6, 1, 0) + IF(AND($E6=BA6, $G6=BB6), 1, 0)))) -> 0 | BD6: =IF(OR(BA6="", BB6="", $E6="", $G6=""), 0, IF(AND($E6=BA6, $G6=BB6), 1, 0)) -> 0 | BG6: =IF(OR(BE6="", BF6=""), 0, IF(OR($E6="", $G6=""), "", (IF(SIGN($E6-$G6)=SIGN(BE6-BF6), 2, 0) + IF($E6=BE6, 1, 0) + IF($G6=BF6, 1, 0) + IF(AND($E6=BE6, $G6=BF6), 1, 0)))) -> 0 | BH6: =IF(OR(BE6="", BF6="", $E6="", $G6=""), 0, IF(AND($E6=BE6, $G6=BF6), 1, 0)) -> 0 | BK6: =IF(OR(BI6="", BJ6=""), 0, IF(OR($E6="", $G6=""), "", (IF(SIGN($E6-$G6)=SIGN(BI6-BJ6), 2, 0) + IF($E6=BI6, 1, 0) + IF($G6=BJ6, 1, 0) + IF(AND($E6=BI6, $G6=BJ6), 1, 0)))) -> 0 | BL6: =IF(OR(BI6="", BJ6="", $E6="", $G6=""), 0, IF(AND($E6=BI6, $G6=BJ6), 1, 0)) -> 0
A7: =CALENDARIO!A7 -> 6 | B7: =CALENDARIO!B7 -> 46186 | C7: =CALENDARIO!C7 -> 0.79166667 | D7: =CALENDARIO!D7 -> Brasil | E7: =CALENDARIO!E7 -> 0 | F7: =CALENDARIO!F7 -> x | G7: =CALENDARIO!G7 -> 0 | H7: =CALENDARIO!H7 -> Marrocos | K7: =IF(OR(I7="", J7=""), 0, IF(OR($E7="", $G7=""), "", (IF(SIGN($E7-$G7)=SIGN(I7-J7), 2, 0) + IF($E7=I7, 1, 0) + IF($G7=J7, 1, 0) + IF(AND($E7=I7, $G7=J7), 1, 0)))) -> 0 | L7: =IF(OR(I7="", J7="", $E7="", $G7=""), 0, IF(AND($E7=I7, $G7=J7), 1, 0)) -> 0 | O7: =IF(OR(M7="", N7=""), 0, IF(OR($E7="", $G7=""), "", (IF(SIGN($E7-$G7)=SIGN(M7-N7), 2, 0) + IF($E7=M7, 1, 0) + IF($G7=N7, 1, 0) + IF(AND($E7=M7, $G7=N7), 1, 0)))) -> 0 | P7: =IF(OR(M7="", N7="", $E7="", $G7=""), 0, IF(AND($E7=M7, $G7=N7), 1, 0)) -> 0 | S7: =IF(OR(Q7="", R7=""), 0, IF(OR($E7="", $G7=""), "", (IF(SIGN($E7-$G7)=SIGN(Q7-R7), 2, 0) + IF($E7=Q7, 1, 0) + IF($G7=R7, 1, 0) + IF(AND($E7=Q7, $G7=R7), 1, 0)))) -> 0 | T7: =IF(OR(Q7="", R7="", $E7="", $G7=""), 0, IF(AND($E7=Q7, $G7=R7), 1, 0)) -> 0 | W7: =IF(OR(U7="", V7=""), 0, IF(OR($E7="", $G7=""), "", (IF(SIGN($E7-$G7)=SIGN(U7-V7), 2, 0) + IF($E7=U7, 1, 0) + IF($G7=V7, 1, 0) + IF(AND($E7=U7, $G7=V7), 1, 0)))) -> 0 | X7: =IF(OR(U7="", V7="", $E7="", $G7=""), 0, IF(AND($E7=U7, $G7=V7), 1, 0)) -> 0 | AA7: =IF(OR(Y7="", Z7=""), 0, IF(OR($E7="", $G7=""), "", (IF(SIGN($E7-$G7)=SIGN(Y7-Z7), 2, 0) + IF($E7=Y7, 1, 0) + IF($G7=Z7, 1, 0) + IF(AND($E7=Y7, $G7=Z7), 1, 0)))) -> 0 | AB7: =IF(OR(Y7="", Z7="", $E7="", $G7=""), 0, IF(AND($E7=Y7, $G7=Z7), 1, 0)) -> 0 | AE7: =IF(OR(AC7="", AD7=""), 0, IF(OR($E7="", $G7=""), "", (IF(SIGN($E7-$G7)=SIGN(AC7-AD7), 2, 0) + IF($E7=AC7, 1, 0) + IF($G7=AD7, 1, 0) + IF(AND($E7=AC7, $G7=AD7), 1, 0)))) -> 0 | AF7: =IF(OR(AC7="", AD7="", $E7="", $G7=""), 0, IF(AND($E7=AC7, $G7=AD7), 1, 0)) -> 0 | AI7: =IF(OR(AG7="", AH7=""), 0, IF(OR($E7="", $G7=""), "", (IF(SIGN($E7-$G7)=SIGN(AG7-AH7), 2, 0) + IF($E7=AG7, 1, 0) + IF($G7=AH7, 1, 0) + IF(AND($E7=AG7, $G7=AH7), 1, 0)))) -> 0 | AJ7: =IF(OR(AG7="", AH7="", $E7="", $G7=""), 0, IF(AND($E7=AG7, $G7=AH7), 1, 0)) -> 0 | AM7: =IF(OR(AK7="", AL7=""), 0, IF(OR($E7="", $G7=""), "", (IF(SIGN($E7-$G7)=SIGN(AK7-AL7), 2, 0) + IF($E7=AK7, 1, 0) + IF($G7=AL7, 1, 0) + IF(AND($E7=AK7, $G7=AL7), 1, 0)))) -> 0 | AN7: =IF(OR(AK7="", AL7="", $E7="", $G7=""), 0, IF(AND($E7=AK7, $G7=AL7), 1, 0)) -> 0 | AQ7: =IF(OR(AO7="", AP7=""), 0, IF(OR($E7="", $G7=""), "", (IF(SIGN($E7-$G7)=SIGN(AO7-AP7), 2, 0) + IF($E7=AO7, 1, 0) + IF($G7=AP7, 1, 0) + IF(AND($E7=AO7, $G7=AP7), 1, 0)))) -> 0 | AR7: =IF(OR(AO7="", AP7="", $E7="", $G7=""), 0, IF(AND($E7=AO7, $G7=AP7), 1, 0)) -> 0 | AU7: =IF(OR(AS7="", AT7=""), 0, IF(OR($E7="", $G7=""), "", (IF(SIGN($E7-$G7)=SIGN(AS7-AT7), 2, 0) + IF($E7=AS7, 1, 0) + IF($G7=AT7, 1, 0) + IF(AND($E7=AS7, $G7=AT7), 1, 0)))) -> 0 | AV7: =IF(OR(AS7="", AT7="", $E7="", $G7=""), 0, IF(AND($E7=AS7, $G7=AT7), 1, 0)) -> 0 | AY7: =IF(OR(AW7="", AX7=""), 0, IF(OR($E7="", $G7=""), "", (IF(SIGN($E7-$G7)=SIGN(AW7-AX7), 2, 0) + IF($E7=AW7, 1, 0) + IF($G7=AX7, 1, 0) + IF(AND($E7=AW7, $G7=AX7), 1, 0)))) -> 0 | AZ7: =IF(OR(AW7="", AX7="", $E7="", $G7=""), 0, IF(AND($E7=AW7, $G7=AX7), 1, 0)) -> 0 | BC7: =IF(OR(BA7="", BB7=""), 0, IF(OR($E7="", $G7=""), "", (IF(SIGN($E7-$G7)=SIGN(BA7-BB7), 2, 0) + IF($E7=BA7, 1, 0) + IF($G7=BB7, 1, 0) + IF(AND($E7=BA7, $G7=BB7), 1, 0)))) -> 0 | BD7: =IF(OR(BA7="", BB7="", $E7="", $G7=""), 0, IF(AND($E7=BA7, $G7=BB7), 1, 0)) -> 0 | BG7: =IF(OR(BE7="", BF7=""), 0, IF(OR($E7="", $G7=""), "", (IF(SIGN($E7-$G7)=SIGN(BE7-BF7), 2, 0) + IF($E7=BE7, 1, 0) + IF($G7=BF7, 1, 0) + IF(AND($E7=BE7, $G7=BF7), 1, 0)))) -> 0 | BH7: =IF(OR(BE7="", BF7="", $E7="", $G7=""), 0, IF(AND($E7=BE7, $G7=BF7), 1, 0)) -> 0 | BK7: =IF(OR(BI7="", BJ7=""), 0, IF(OR($E7="", $G7=""), "", (IF(SIGN($E7-$G7)=SIGN(BI7-BJ7), 2, 0) + IF($E7=BI7, 1, 0) + IF($G7=BJ7, 1, 0) + IF(AND($E7=BI7, $G7=BJ7), 1, 0)))) -> 0 | BL7: =IF(OR(BI7="", BJ7="", $E7="", $G7=""), 0, IF(AND($E7=BI7, $G7=BJ7), 1, 0)) -> 0
A8: =CALENDARIO!A8 -> 7 | B8: =CALENDARIO!B8 -> 46186 | C8: =CALENDARIO!C8 -> 0.91666667 | D8: =CALENDARIO!D8 -> Haiti | E8: =CALENDARIO!E8 -> 0 | F8: =CALENDARIO!F8 -> x | G8: =CALENDARIO!G8 -> 0 | H8: =CALENDARIO!H8 -> Escócia | K8: =IF(OR(I8="", J8=""), 0, IF(OR($E8="", $G8=""), "", (IF(SIGN($E8-$G8)=SIGN(I8-J8), 2, 0) + IF($E8=I8, 1, 0) + IF($G8=J8, 1, 0) + IF(AND($E8=I8, $G8=J8), 1, 0)))) -> 0 | L8: =IF(OR(I8="", J8="", $E8="", $G8=""), 0, IF(AND($E8=I8, $G8=J8), 1, 0)) -> 0 | O8: =IF(OR(M8="", N8=""), 0, IF(OR($E8="", $G8=""), "", (IF(SIGN($E8-$G8)=SIGN(M8-N8), 2, 0) + IF($E8=M8, 1, 0) + IF($G8=N8, 1, 0) + IF(AND($E8=M8, $G8=N8), 1, 0)))) -> 0 | P8: =IF(OR(M8="", N8="", $E8="", $G8=""), 0, IF(AND($E8=M8, $G8=N8), 1, 0)) -> 0 | S8: =IF(OR(Q8="", R8=""), 0, IF(OR($E8="", $G8=""), "", (IF(SIGN($E8-$G8)=SIGN(Q8-R8), 2, 0) + IF($E8=Q8, 1, 0) + IF($G8=R8, 1, 0) + IF(AND($E8=Q8, $G8=R8), 1, 0)))) -> 0 | T8: =IF(OR(Q8="", R8="", $E8="", $G8=""), 0, IF(AND($E8=Q8, $G8=R8), 1, 0)) -> 0 | W8: =IF(OR(U8="", V8=""), 0, IF(OR($E8="", $G8=""), "", (IF(SIGN($E8-$G8)=SIGN(U8-V8), 2, 0) + IF($E8=U8, 1, 0) + IF($G8=V8, 1, 0) + IF(AND($E8=U8, $G8=V8), 1, 0)))) -> 0 | X8: =IF(OR(U8="", V8="", $E8="", $G8=""), 0, IF(AND($E8=U8, $G8=V8), 1, 0)) -> 0 | AA8: =IF(OR(Y8="", Z8=""), 0, IF(OR($E8="", $G8=""), "", (IF(SIGN($E8-$G8)=SIGN(Y8-Z8), 2, 0) + IF($E8=Y8, 1, 0) + IF($G8=Z8, 1, 0) + IF(AND($E8=Y8, $G8=Z8), 1, 0)))) -> 0 | AB8: =IF(OR(Y8="", Z8="", $E8="", $G8=""), 0, IF(AND($E8=Y8, $G8=Z8), 1, 0)) -> 0 | AE8: =IF(OR(AC8="", AD8=""), 0, IF(OR($E8="", $G8=""), "", (IF(SIGN($E8-$G8)=SIGN(AC8-AD8), 2, 0) + IF($E8=AC8, 1, 0) + IF($G8=AD8, 1, 0) + IF(AND($E8=AC8, $G8=AD8), 1, 0)))) -> 0 | AF8: =IF(OR(AC8="", AD8="", $E8="", $G8=""), 0, IF(AND($E8=AC8, $G8=AD8), 1, 0)) -> 0 | AI8: =IF(OR(AG8="", AH8=""), 0, IF(OR($E8="", $G8=""), "", (IF(SIGN($E8-$G8)=SIGN(AG8-AH8), 2, 0) + IF($E8=AG8, 1, 0) + IF($G8=AH8, 1, 0) + IF(AND($E8=AG8, $G8=AH8), 1, 0)))) -> 0 | AJ8: =IF(OR(AG8="", AH8="", $E8="", $G8=""), 0, IF(AND($E8=AG8, $G8=AH8), 1, 0)) -> 0 | AM8: =IF(OR(AK8="", AL8=""), 0, IF(OR($E8="", $G8=""), "", (IF(SIGN($E8-$G8)=SIGN(AK8-AL8), 2, 0) + IF($E8=AK8, 1, 0) + IF($G8=AL8, 1, 0) + IF(AND($E8=AK8, $G8=AL8), 1, 0)))) -> 0 | AN8: =IF(OR(AK8="", AL8="", $E8="", $G8=""), 0, IF(AND($E8=AK8, $G8=AL8), 1, 0)) -> 0 | AQ8: =IF(OR(AO8="", AP8=""), 0, IF(OR($E8="", $G8=""), "", (IF(SIGN($E8-$G8)=SIGN(AO8-AP8), 2, 0) + IF($E8=AO8, 1, 0) + IF($G8=AP8, 1, 0) + IF(AND($E8=AO8, $G8=AP8), 1, 0)))) -> 0 | AR8: =IF(OR(AO8="", AP8="", $E8="", $G8=""), 0, IF(AND($E8=AO8, $G8=AP8), 1, 0)) -> 0 | AU8: =IF(OR(AS8="", AT8=""), 0, IF(OR($E8="", $G8=""), "", (IF(SIGN($E8-$G8)=SIGN(AS8-AT8), 2, 0) + IF($E8=AS8, 1, 0) + IF($G8=AT8, 1, 0) + IF(AND($E8=AS8, $G8=AT8), 1, 0)))) -> 0 | AV8: =IF(OR(AS8="", AT8="", $E8="", $G8=""), 0, IF(AND($E8=AS8, $G8=AT8), 1, 0)) -> 0 | AY8: =IF(OR(AW8="", AX8=""), 0, IF(OR($E8="", $G8=""), "", (IF(SIGN($E8-$G8)=SIGN(AW8-AX8), 2, 0) + IF($E8=AW8, 1, 0) + IF($G8=AX8, 1, 0) + IF(AND($E8=AW8, $G8=AX8), 1, 0)))) -> 0 | AZ8: =IF(OR(AW8="", AX8="", $E8="", $G8=""), 0, IF(AND($E8=AW8, $G8=AX8), 1, 0)) -> 0 | BC8: =IF(OR(BA8="", BB8=""), 0, IF(OR($E8="", $G8=""), "", (IF(SIGN($E8-$G8)=SIGN(BA8-BB8), 2, 0) + IF($E8=BA8, 1, 0) + IF($G8=BB8, 1, 0) + IF(AND($E8=BA8, $G8=BB8), 1, 0)))) -> 0 | BD8: =IF(OR(BA8="", BB8="", $E8="", $G8=""), 0, IF(AND($E8=BA8, $G8=BB8), 1, 0)) -> 0 | BG8: =IF(OR(BE8="", BF8=""), 0, IF(OR($E8="", $G8=""), "", (IF(SIGN($E8-$G8)=SIGN(BE8-BF8), 2, 0) + IF($E8=BE8, 1, 0) + IF($G8=BF8, 1, 0) + IF(AND($E8=BE8, $G8=BF8), 1, 0)))) -> 0 | BH8: =IF(OR(BE8="", BF8="", $E8="", $G8=""), 0, IF(AND($E8=BE8, $G8=BF8), 1, 0)) -> 0 | BK8: =IF(OR(BI8="", BJ8=""), 0, IF(OR($E8="", $G8=""), "", (IF(SIGN($E8-$G8)=SIGN(BI8-BJ8), 2, 0) + IF($E8=BI8, 1, 0) + IF($G8=BJ8, 1, 0) + IF(AND($E8=BI8, $G8=BJ8), 1, 0)))) -> 0 | BL8: =IF(OR(BI8="", BJ8="", $E8="", $G8=""), 0, IF(AND($E8=BI8, $G8=BJ8), 1, 0)) -> 0
A9: =CALENDARIO!A9 -> 8 | B9: =CALENDARIO!B9 -> 46187 | C9: =CALENDARIO!C9 -> 0.041666667 | D9: =CALENDARIO!D9 -> Austrália | E9: =CALENDARIO!E9 -> 0 | F9: =CALENDARIO!F9 -> x | G9: =CALENDARIO!G9 -> 0 | H9: =CALENDARIO!H9 -> Turquia | K9: =IF(OR(I9="", J9=""), 0, IF(OR($E9="", $G9=""), "", (IF(SIGN($E9-$G9)=SIGN(I9-J9), 2, 0) + IF($E9=I9, 1, 0) + IF($G9=J9, 1, 0) + IF(AND($E9=I9, $G9=J9), 1, 0)))) -> 0 | L9: =IF(OR(I9="", J9="", $E9="", $G9=""), 0, IF(AND($E9=I9, $G9=J9), 1, 0)) -> 0 | O9: =IF(OR(M9="", N9=""), 0, IF(OR($E9="", $G9=""), "", (IF(SIGN($E9-$G9)=SIGN(M9-N9), 2, 0) + IF($E9=M9, 1, 0) + IF($G9=N9, 1, 0) + IF(AND($E9=M9, $G9=N9), 1, 0)))) -> 0 | P9: =IF(OR(M9="", N9="", $E9="", $G9=""), 0, IF(AND($E9=M9, $G9=N9), 1, 0)) -> 0 | S9: =IF(OR(Q9="", R9=""), 0, IF(OR($E9="", $G9=""), "", (IF(SIGN($E9-$G9)=SIGN(Q9-R9), 2, 0) + IF($E9=Q9, 1, 0) + IF($G9=R9, 1, 0) + IF(AND($E9=Q9, $G9=R9), 1, 0)))) -> 0 | T9: =IF(OR(Q9="", R9="", $E9="", $G9=""), 0, IF(AND($E9=Q9, $G9=R9), 1, 0)) -> 0 | W9: =IF(OR(U9="", V9=""), 0, IF(OR($E9="", $G9=""), "", (IF(SIGN($E9-$G9)=SIGN(U9-V9), 2, 0) + IF($E9=U9, 1, 0) + IF($G9=V9, 1, 0) + IF(AND($E9=U9, $G9=V9), 1, 0)))) -> 0 | X9: =IF(OR(U9="", V9="", $E9="", $G9=""), 0, IF(AND($E9=U9, $G9=V9), 1, 0)) -> 0 | AA9: =IF(OR(Y9="", Z9=""), 0, IF(OR($E9="", $G9=""), "", (IF(SIGN($E9-$G9)=SIGN(Y9-Z9), 2, 0) + IF($E9=Y9, 1, 0) + IF($G9=Z9, 1, 0) + IF(AND($E9=Y9, $G9=Z9), 1, 0)))) -> 0 | AB9: =IF(OR(Y9="", Z9="", $E9="", $G9=""), 0, IF(AND($E9=Y9, $G9=Z9), 1, 0)) -> 0 | AE9: =IF(OR(AC9="", AD9=""), 0, IF(OR($E9="", $G9=""), "", (IF(SIGN($E9-$G9)=SIGN(AC9-AD9), 2, 0) + IF($E9=AC9, 1, 0) + IF($G9=AD9, 1, 0) + IF(AND($E9=AC9, $G9=AD9), 1, 0)))) -> 0 | AF9: =IF(OR(AC9="", AD9="", $E9="", $G9=""), 0, IF(AND($E9=AC9, $G9=AD9), 1, 0)) -> 0 | AI9: =IF(OR(AG9="", AH9=""), 0, IF(OR($E9="", $G9=""), "", (IF(SIGN($E9-$G9)=SIGN(AG9-AH9), 2, 0) + IF($E9=AG9, 1, 0) + IF($G9=AH9, 1, 0) + IF(AND($E9=AG9, $G9=AH9), 1, 0)))) -> 0 | AJ9: =IF(OR(AG9="", AH9="", $E9="", $G9=""), 0, IF(AND($E9=AG9, $G9=AH9), 1, 0)) -> 0 | AM9: =IF(OR(AK9="", AL9=""), 0, IF(OR($E9="", $G9=""), "", (IF(SIGN($E9-$G9)=SIGN(AK9-AL9), 2, 0) + IF($E9=AK9, 1, 0) + IF($G9=AL9, 1, 0) + IF(AND($E9=AK9, $G9=AL9), 1, 0)))) -> 0 | AN9: =IF(OR(AK9="", AL9="", $E9="", $G9=""), 0, IF(AND($E9=AK9, $G9=AL9), 1, 0)) -> 0 | AQ9: =IF(OR(AO9="", AP9=""), 0, IF(OR($E9="", $G9=""), "", (IF(SIGN($E9-$G9)=SIGN(AO9-AP9), 2, 0) + IF($E9=AO9, 1, 0) + IF($G9=AP9, 1, 0) + IF(AND($E9=AO9, $G9=AP9), 1, 0)))) -> 0 | AR9: =IF(OR(AO9="", AP9="", $E9="", $G9=""), 0, IF(AND($E9=AO9, $G9=AP9), 1, 0)) -> 0 | AU9: =IF(OR(AS9="", AT9=""), 0, IF(OR($E9="", $G9=""), "", (IF(SIGN($E9-$G9)=SIGN(AS9-AT9), 2, 0) + IF($E9=AS9, 1, 0) + IF($G9=AT9, 1, 0) + IF(AND($E9=AS9, $G9=AT9), 1, 0)))) -> 0 | AV9: =IF(OR(AS9="", AT9="", $E9="", $G9=""), 0, IF(AND($E9=AS9, $G9=AT9), 1, 0)) -> 0 | AY9: =IF(OR(AW9="", AX9=""), 0, IF(OR($E9="", $G9=""), "", (IF(SIGN($E9-$G9)=SIGN(AW9-AX9), 2, 0) + IF($E9=AW9, 1, 0) + IF($G9=AX9, 1, 0) + IF(AND($E9=AW9, $G9=AX9), 1, 0)))) -> 0 | AZ9: =IF(OR(AW9="", AX9="", $E9="", $G9=""), 0, IF(AND($E9=AW9, $G9=AX9), 1, 0)) -> 0 | BC9: =IF(OR(BA9="", BB9=""), 0, IF(OR($E9="", $G9=""), "", (IF(SIGN($E9-$G9)=SIGN(BA9-BB9), 2, 0) + IF($E9=BA9, 1, 0) + IF($G9=BB9, 1, 0) + IF(AND($E9=BA9, $G9=BB9), 1, 0)))) -> 0 | BD9: =IF(OR(BA9="", BB9="", $E9="", $G9=""), 0, IF(AND($E9=BA9, $G9=BB9), 1, 0)) -> 0 | BG9: =IF(OR(BE9="", BF9=""), 0, IF(OR($E9="", $G9=""), "", (IF(SIGN($E9-$G9)=SIGN(BE9-BF9), 2, 0) + IF($E9=BE9, 1, 0) + IF($G9=BF9, 1, 0) + IF(AND($E9=BE9, $G9=BF9), 1, 0)))) -> 0 | BH9: =IF(OR(BE9="", BF9="", $E9="", $G9=""), 0, IF(AND($E9=BE9, $G9=BF9), 1, 0)) -> 0 | BK9: =IF(OR(BI9="", BJ9=""), 0, IF(OR($E9="", $G9=""), "", (IF(SIGN($E9-$G9)=SIGN(BI9-BJ9), 2, 0) + IF($E9=BI9, 1, 0) + IF($G9=BJ9, 1, 0) + IF(AND($E9=BI9, $G9=BJ9), 1, 0)))) -> 0 | BL9: =IF(OR(BI9="", BJ9="", $E9="", $G9=""), 0, IF(AND($E9=BI9, $G9=BJ9), 1, 0)) -> 0
A10: =CALENDARIO!A10 -> 9 | B10: =CALENDARIO!B10 -> 46187 | C10: =CALENDARIO!C10 -> 0.58333333 | D10: =CALENDARIO!D10 -> Alemanha | E10: =CALENDARIO!E10 -> 0 | F10: =CALENDARIO!F10 -> x | G10: =CALENDARIO!G10 -> 0 | H10: =CALENDARIO!H10 -> Curaçau | K10: =IF(OR(I10="", J10=""), 0, IF(OR($E10="", $G10=""), "", (IF(SIGN($E10-$G10)=SIGN(I10-J10), 2, 0) + IF($E10=I10, 1, 0) + IF($G10=J10, 1, 0) + IF(AND($E10=I10, $G10=J10), 1, 0)))) -> 0 | L10: =IF(OR(I10="", J10="", $E10="", $G10=""), 0, IF(AND($E10=I10, $G10=J10), 1, 0)) -> 0 | O10: =IF(OR(M10="", N10=""), 0, IF(OR($E10="", $G10=""), "", (IF(SIGN($E10-$G10)=SIGN(M10-N10), 2, 0) + IF($E10=M10, 1, 0) + IF($G10=N10, 1, 0) + IF(AND($E10=M10, $G10=N10), 1, 0)))) -> 0 | P10: =IF(OR(M10="", N10="", $E10="", $G10=""), 0, IF(AND($E10=M10, $G10=N10), 1, 0)) -> 0 | S10: =IF(OR(Q10="", R10=""), 0, IF(OR($E10="", $G10=""), "", (IF(SIGN($E10-$G10)=SIGN(Q10-R10), 2, 0) + IF($E10=Q10, 1, 0) + IF($G10=R10, 1, 0) + IF(AND($E10=Q10, $G10=R10), 1, 0)))) -> 0 | T10: =IF(OR(Q10="", R10="", $E10="", $G10=""), 0, IF(AND($E10=Q10, $G10=R10), 1, 0)) -> 0 | W10: =IF(OR(U10="", V10=""), 0, IF(OR($E10="", $G10=""), "", (IF(SIGN($E10-$G10)=SIGN(U10-V10), 2, 0) + IF($E10=U10, 1, 0) + IF($G10=V10, 1, 0) + IF(AND($E10=U10, $G10=V10), 1, 0)))) -> 0 | X10: =IF(OR(U10="", V10="", $E10="", $G10=""), 0, IF(AND($E10=U10, $G10=V10), 1, 0)) -> 0 | AA10: =IF(OR(Y10="", Z10=""), 0, IF(OR($E10="", $G10=""), "", (IF(SIGN($E10-$G10)=SIGN(Y10-Z10), 2, 0) + IF($E10=Y10, 1, 0) + IF($G10=Z10, 1, 0) + IF(AND($E10=Y10, $G10=Z10), 1, 0)))) -> 0 | AB10: =IF(OR(Y10="", Z10="", $E10="", $G10=""), 0, IF(AND($E10=Y10, $G10=Z10), 1, 0)) -> 0 | AE10: =IF(OR(AC10="", AD10=""), 0, IF(OR($E10="", $G10=""), "", (IF(SIGN($E10-$G10)=SIGN(AC10-AD10), 2, 0) + IF($E10=AC10, 1, 0) + IF($G10=AD10, 1, 0) + IF(AND($E10=AC10, $G10=AD10), 1, 0)))) -> 0 | AF10: =IF(OR(AC10="", AD10="", $E10="", $G10=""), 0, IF(AND($E10=AC10, $G10=AD10), 1, 0)) -> 0 | AI10: =IF(OR(AG10="", AH10=""), 0, IF(OR($E10="", $G10=""), "", (IF(SIGN($E10-$G10)=SIGN(AG10-AH10), 2, 0) + IF($E10=AG10, 1, 0) + IF($G10=AH10, 1, 0) + IF(AND($E10=AG10, $G10=AH10), 1, 0)))) -> 0 | AJ10: =IF(OR(AG10="", AH10="", $E10="", $G10=""), 0, IF(AND($E10=AG10, $G10=AH10), 1, 0)) -> 0 | AM10: =IF(OR(AK10="", AL10=""), 0, IF(OR($E10="", $G10=""), "", (IF(SIGN($E10-$G10)=SIGN(AK10-AL10), 2, 0) + IF($E10=AK10, 1, 0) + IF($G10=AL10, 1, 0) + IF(AND($E10=AK10, $G10=AL10), 1, 0)))) -> 0 | AN10: =IF(OR(AK10="", AL10="", $E10="", $G10=""), 0, IF(AND($E10=AK10, $G10=AL10), 1, 0)) -> 0 | AQ10: =IF(OR(AO10="", AP10=""), 0, IF(OR($E10="", $G10=""), "", (IF(SIGN($E10-$G10)=SIGN(AO10-AP10), 2, 0) + IF($E10=AO10, 1, 0) + IF($G10=AP10, 1, 0) + IF(AND($E10=AO10, $G10=AP10), 1, 0)))) -> 0 | AR10: =IF(OR(AO10="", AP10="", $E10="", $G10=""), 0, IF(AND($E10=AO10, $G10=AP10), 1, 0)) -> 0 | AU10: =IF(OR(AS10="", AT10=""), 0, IF(OR($E10="", $G10=""), "", (IF(SIGN($E10-$G10)=SIGN(AS10-AT10), 2, 0) + IF($E10=AS10, 1, 0) + IF($G10=AT10, 1, 0) + IF(AND($E10=AS10, $G10=AT10), 1, 0)))) -> 0 | AV10: =IF(OR(AS10="", AT10="", $E10="", $G10=""), 0, IF(AND($E10=AS10, $G10=AT10), 1, 0)) -> 0 | AY10: =IF(OR(AW10="", AX10=""), 0, IF(OR($E10="", $G10=""), "", (IF(SIGN($E10-$G10)=SIGN(AW10-AX10), 2, 0) + IF($E10=AW10, 1, 0) + IF($G10=AX10, 1, 0) + IF(AND($E10=AW10, $G10=AX10), 1, 0)))) -> 0 | AZ10: =IF(OR(AW10="", AX10="", $E10="", $G10=""), 0, IF(AND($E10=AW10, $G10=AX10), 1, 0)) -> 0 | BC10: =IF(OR(BA10="", BB10=""), 0, IF(OR($E10="", $G10=""), "", (IF(SIGN($E10-$G10)=SIGN(BA10-BB10), 2, 0) + IF($E10=BA10, 1, 0) + IF($G10=BB10, 1, 0) + IF(AND($E10=BA10, $G10=BB10), 1, 0)))) -> 0 | BD10: =IF(OR(BA10="", BB10="", $E10="", $G10=""), 0, IF(AND($E10=BA10, $G10=BB10), 1, 0)) -> 0 | BG10: =IF(OR(BE10="", BF10=""), 0, IF(OR($E10="", $G10=""), "", (IF(SIGN($E10-$G10)=SIGN(BE10-BF10), 2, 0) + IF($E10=BE10, 1, 0) + IF($G10=BF10, 1, 0) + IF(AND($E10=BE10, $G10=BF10), 1, 0)))) -> 0 | BH10: =IF(OR(BE10="", BF10="", $E10="", $G10=""), 0, IF(AND($E10=BE10, $G10=BF10), 1, 0)) -> 0 | BK10: =IF(OR(BI10="", BJ10=""), 0, IF(OR($E10="", $G10=""), "", (IF(SIGN($E10-$G10)=SIGN(BI10-BJ10), 2, 0) + IF($E10=BI10, 1, 0) + IF($G10=BJ10, 1, 0) + IF(AND($E10=BI10, $G10=BJ10), 1, 0)))) -> 0 | BL10: =IF(OR(BI10="", BJ10="", $E10="", $G10=""), 0, IF(AND($E10=BI10, $G10=BJ10), 1, 0)) -> 0
A11: =CALENDARIO!A11 -> 10 | B11: =CALENDARIO!B11 -> 46187 | C11: =CALENDARIO!C11 -> 0.83333333 | D11: =CALENDARIO!D11 -> Costa do Marfim | E11: =CALENDARIO!E11 -> 0 | F11: =CALENDARIO!F11 -> x | G11: =CALENDARIO!G11 -> 0 | H11: =CALENDARIO!H11 -> Equador | K11: =IF(OR(I11="", J11=""), 0, IF(OR($E11="", $G11=""), "", (IF(SIGN($E11-$G11)=SIGN(I11-J11), 2, 0) + IF($E11=I11, 1, 0) + IF($G11=J11, 1, 0) + IF(AND($E11=I11, $G11=J11), 1, 0)))) -> 0 | L11: =IF(OR(I11="", J11="", $E11="", $G11=""), 0, IF(AND($E11=I11, $G11=J11), 1, 0)) -> 0 | O11: =IF(OR(M11="", N11=""), 0, IF(OR($E11="", $G11=""), "", (IF(SIGN($E11-$G11)=SIGN(M11-N11), 2, 0) + IF($E11=M11, 1, 0) + IF($G11=N11, 1, 0) + IF(AND($E11=M11, $G11=N11), 1, 0)))) -> 0 | P11: =IF(OR(M11="", N11="", $E11="", $G11=""), 0, IF(AND($E11=M11, $G11=N11), 1, 0)) -> 0 | S11: =IF(OR(Q11="", R11=""), 0, IF(OR($E11="", $G11=""), "", (IF(SIGN($E11-$G11)=SIGN(Q11-R11), 2, 0) + IF($E11=Q11, 1, 0) + IF($G11=R11, 1, 0) + IF(AND($E11=Q11, $G11=R11), 1, 0)))) -> 0 | T11: =IF(OR(Q11="", R11="", $E11="", $G11=""), 0, IF(AND($E11=Q11, $G11=R11), 1, 0)) -> 0 | W11: =IF(OR(U11="", V11=""), 0, IF(OR($E11="", $G11=""), "", (IF(SIGN($E11-$G11)=SIGN(U11-V11), 2, 0) + IF($E11=U11, 1, 0) + IF($G11=V11, 1, 0) + IF(AND($E11=U11, $G11=V11), 1, 0)))) -> 0 | X11: =IF(OR(U11="", V11="", $E11="", $G11=""), 0, IF(AND($E11=U11, $G11=V11), 1, 0)) -> 0 | AA11: =IF(OR(Y11="", Z11=""), 0, IF(OR($E11="", $G11=""), "", (IF(SIGN($E11-$G11)=SIGN(Y11-Z11), 2, 0) + IF($E11=Y11, 1, 0) + IF($G11=Z11, 1, 0) + IF(AND($E11=Y11, $G11=Z11), 1, 0)))) -> 0 | AB11: =IF(OR(Y11="", Z11="", $E11="", $G11=""), 0, IF(AND($E11=Y11, $G11=Z11), 1, 0)) -> 0 | AE11: =IF(OR(AC11="", AD11=""), 0, IF(OR($E11="", $G11=""), "", (IF(SIGN($E11-$G11)=SIGN(AC11-AD11), 2, 0) + IF($E11=AC11, 1, 0) + IF($G11=AD11, 1, 0) + IF(AND($E11=AC11, $G11=AD11), 1, 0)))) -> 0 | AF11: =IF(OR(AC11="", AD11="", $E11="", $G11=""), 0, IF(AND($E11=AC11, $G11=AD11), 1, 0)) -> 0 | AI11: =IF(OR(AG11="", AH11=""), 0, IF(OR($E11="", $G11=""), "", (IF(SIGN($E11-$G11)=SIGN(AG11-AH11), 2, 0) + IF($E11=AG11, 1, 0) + IF($G11=AH11, 1, 0) + IF(AND($E11=AG11, $G11=AH11), 1, 0)))) -> 0 | AJ11: =IF(OR(AG11="", AH11="", $E11="", $G11=""), 0, IF(AND($E11=AG11, $G11=AH11), 1, 0)) -> 0 | AM11: =IF(OR(AK11="", AL11=""), 0, IF(OR($E11="", $G11=""), "", (IF(SIGN($E11-$G11)=SIGN(AK11-AL11), 2, 0) + IF($E11=AK11, 1, 0) + IF($G11=AL11, 1, 0) + IF(AND($E11=AK11, $G11=AL11), 1, 0)))) -> 0 | AN11: =IF(OR(AK11="", AL11="", $E11="", $G11=""), 0, IF(AND($E11=AK11, $G11=AL11), 1, 0)) -> 0 | AQ11: =IF(OR(AO11="", AP11=""), 0, IF(OR($E11="", $G11=""), "", (IF(SIGN($E11-$G11)=SIGN(AO11-AP11), 2, 0) + IF($E11=AO11, 1, 0) + IF($G11=AP11, 1, 0) + IF(AND($E11=AO11, $G11=AP11), 1, 0)))) -> 0 | AR11: =IF(OR(AO11="", AP11="", $E11="", $G11=""), 0, IF(AND($E11=AO11, $G11=AP11), 1, 0)) -> 0 | AU11: =IF(OR(AS11="", AT11=""), 0, IF(OR($E11="", $G11=""), "", (IF(SIGN($E11-$G11)=SIGN(AS11-AT11), 2, 0) + IF($E11=AS11, 1, 0) + IF($G11=AT11, 1, 0) + IF(AND($E11=AS11, $G11=AT11), 1, 0)))) -> 0 | AV11: =IF(OR(AS11="", AT11="", $E11="", $G11=""), 0, IF(AND($E11=AS11, $G11=AT11), 1, 0)) -> 0 | AY11: =IF(OR(AW11="", AX11=""), 0, IF(OR($E11="", $G11=""), "", (IF(SIGN($E11-$G11)=SIGN(AW11-AX11), 2, 0) + IF($E11=AW11, 1, 0) + IF($G11=AX11, 1, 0) + IF(AND($E11=AW11, $G11=AX11), 1, 0)))) -> 0 | AZ11: =IF(OR(AW11="", AX11="", $E11="", $G11=""), 0, IF(AND($E11=AW11, $G11=AX11), 1, 0)) -> 0 | BC11: =IF(OR(BA11="", BB11=""), 0, IF(OR($E11="", $G11=""), "", (IF(SIGN($E11-$G11)=SIGN(BA11-BB11), 2, 0) + IF($E11=BA11, 1, 0) + IF($G11=BB11, 1, 0) + IF(AND($E11=BA11, $G11=BB11), 1, 0)))) -> 0 | BD11: =IF(OR(BA11="", BB11="", $E11="", $G11=""), 0, IF(AND($E11=BA11, $G11=BB11), 1, 0)) -> 0 | BG11: =IF(OR(BE11="", BF11=""), 0, IF(OR($E11="", $G11=""), "", (IF(SIGN($E11-$G11)=SIGN(BE11-BF11), 2, 0) + IF($E11=BE11, 1, 0) + IF($G11=BF11, 1, 0) + IF(AND($E11=BE11, $G11=BF11), 1, 0)))) -> 0 | BH11: =IF(OR(BE11="", BF11="", $E11="", $G11=""), 0, IF(AND($E11=BE11, $G11=BF11), 1, 0)) -> 0 | BK11: =IF(OR(BI11="", BJ11=""), 0, IF(OR($E11="", $G11=""), "", (IF(SIGN($E11-$G11)=SIGN(BI11-BJ11), 2, 0) + IF($E11=BI11, 1, 0) + IF($G11=BJ11, 1, 0) + IF(AND($E11=BI11, $G11=BJ11), 1, 0)))) -> 0 | BL11: =IF(OR(BI11="", BJ11="", $E11="", $G11=""), 0, IF(AND($E11=BI11, $G11=BJ11), 1, 0)) -> 0
A12: =CALENDARIO!A12 -> 11 | B12: =CALENDARIO!B12 -> 46187 | C12: =CALENDARIO!C12 -> 0.70833333 | D12: =CALENDARIO!D12 -> Holanda | E12: =CALENDARIO!E12 -> 0 | F12: =CALENDARIO!F12 -> x | G12: =CALENDARIO!G12 -> 0 | H12: =CALENDARIO!H12 -> Japão | K12: =IF(OR(I12="", J12=""), 0, IF(OR($E12="", $G12=""), "", (IF(SIGN($E12-$G12)=SIGN(I12-J12), 2, 0) + IF($E12=I12, 1, 0) + IF($G12=J12, 1, 0) + IF(AND($E12=I12, $G12=J12), 1, 0)))) -> 0 | L12: =IF(OR(I12="", J12="", $E12="", $G12=""), 0, IF(AND($E12=I12, $G12=J12), 1, 0)) -> 0 | O12: =IF(OR(M12="", N12=""), 0, IF(OR($E12="", $G12=""), "", (IF(SIGN($E12-$G12)=SIGN(M12-N12), 2, 0) + IF($E12=M12, 1, 0) + IF($G12=N12, 1, 0) + IF(AND($E12=M12, $G12=N12), 1, 0)))) -> 0 | P12: =IF(OR(M12="", N12="", $E12="", $G12=""), 0, IF(AND($E12=M12, $G12=N12), 1, 0)) -> 0 | S12: =IF(OR(Q12="", R12=""), 0, IF(OR($E12="", $G12=""), "", (IF(SIGN($E12-$G12)=SIGN(Q12-R12), 2, 0) + IF($E12=Q12, 1, 0) + IF($G12=R12, 1, 0) + IF(AND($E12=Q12, $G12=R12), 1, 0)))) -> 0 | T12: =IF(OR(Q12="", R12="", $E12="", $G12=""), 0, IF(AND($E12=Q12, $G12=R12), 1, 0)) -> 0 | W12: =IF(OR(U12="", V12=""), 0, IF(OR($E12="", $G12=""), "", (IF(SIGN($E12-$G12)=SIGN(U12-V12), 2, 0) + IF($E12=U12, 1, 0) + IF($G12=V12, 1, 0) + IF(AND($E12=U12, $G12=V12), 1, 0)))) -> 0 | X12: =IF(OR(U12="", V12="", $E12="", $G12=""), 0, IF(AND($E12=U12, $G12=V12), 1, 0)) -> 0 | AA12: =IF(OR(Y12="", Z12=""), 0, IF(OR($E12="", $G12=""), "", (IF(SIGN($E12-$G12)=SIGN(Y12-Z12), 2, 0) + IF($E12=Y12, 1, 0) + IF($G12=Z12, 1, 0) + IF(AND($E12=Y12, $G12=Z12), 1, 0)))) -> 0 | AB12: =IF(OR(Y12="", Z12="", $E12="", $G12=""), 0, IF(AND($E12=Y12, $G12=Z12), 1, 0)) -> 0 | AE12: =IF(OR(AC12="", AD12=""), 0, IF(OR($E12="", $G12=""), "", (IF(SIGN($E12-$G12)=SIGN(AC12-AD12), 2, 0) + IF($E12=AC12, 1, 0) + IF($G12=AD12, 1, 0) + IF(AND($E12=AC12, $G12=AD12), 1, 0)))) -> 0 | AF12: =IF(OR(AC12="", AD12="", $E12="", $G12=""), 0, IF(AND($E12=AC12, $G12=AD12), 1, 0)) -> 0 | AI12: =IF(OR(AG12="", AH12=""), 0, IF(OR($E12="", $G12=""), "", (IF(SIGN($E12-$G12)=SIGN(AG12-AH12), 2, 0) + IF($E12=AG12, 1, 0) + IF($G12=AH12, 1, 0) + IF(AND($E12=AG12, $G12=AH12), 1, 0)))) -> 0 | AJ12: =IF(OR(AG12="", AH12="", $E12="", $G12=""), 0, IF(AND($E12=AG12, $G12=AH12), 1, 0)) -> 0 | AM12: =IF(OR(AK12="", AL12=""), 0, IF(OR($E12="", $G12=""), "", (IF(SIGN($E12-$G12)=SIGN(AK12-AL12), 2, 0) + IF($E12=AK12, 1, 0) + IF($G12=AL12, 1, 0) + IF(AND($E12=AK12, $G12=AL12), 1, 0)))) -> 0 | AN12: =IF(OR(AK12="", AL12="", $E12="", $G12=""), 0, IF(AND($E12=AK12, $G12=AL12), 1, 0)) -> 0 | AQ12: =IF(OR(AO12="", AP12=""), 0, IF(OR($E12="", $G12=""), "", (IF(SIGN($E12-$G12)=SIGN(AO12-AP12), 2, 0) + IF($E12=AO12, 1, 0) + IF($G12=AP12, 1, 0) + IF(AND($E12=AO12, $G12=AP12), 1, 0)))) -> 0 | AR12: =IF(OR(AO12="", AP12="", $E12="", $G12=""), 0, IF(AND($E12=AO12, $G12=AP12), 1, 0)) -> 0 | AU12: =IF(OR(AS12="", AT12=""), 0, IF(OR($E12="", $G12=""), "", (IF(SIGN($E12-$G12)=SIGN(AS12-AT12), 2, 0) + IF($E12=AS12, 1, 0) + IF($G12=AT12, 1, 0) + IF(AND($E12=AS12, $G12=AT12), 1, 0)))) -> 0 | AV12: =IF(OR(AS12="", AT12="", $E12="", $G12=""), 0, IF(AND($E12=AS12, $G12=AT12), 1, 0)) -> 0 | AY12: =IF(OR(AW12="", AX12=""), 0, IF(OR($E12="", $G12=""), "", (IF(SIGN($E12-$G12)=SIGN(AW12-AX12), 2, 0) + IF($E12=AW12, 1, 0) + IF($G12=AX12, 1, 0) + IF(AND($E12=AW12, $G12=AX12), 1, 0)))) -> 0 | AZ12: =IF(OR(AW12="", AX12="", $E12="", $G12=""), 0, IF(AND($E12=AW12, $G12=AX12), 1, 0)) -> 0 | BC12: =IF(OR(BA12="", BB12=""), 0, IF(OR($E12="", $G12=""), "", (IF(SIGN($E12-$G12)=SIGN(BA12-BB12), 2, 0) + IF($E12=BA12, 1, 0) + IF($G12=BB12, 1, 0) + IF(AND($E12=BA12, $G12=BB12), 1, 0)))) -> 0 | BD12: =IF(OR(BA12="", BB12="", $E12="", $G12=""), 0, IF(AND($E12=BA12, $G12=BB12), 1, 0)) -> 0 | BG12: =IF(OR(BE12="", BF12=""), 0, IF(OR($E12="", $G12=""), "", (IF(SIGN($E12-$G12)=SIGN(BE12-BF12), 2, 0) + IF($E12=BE12, 1, 0) + IF($G12=BF12, 1, 0) + IF(AND($E12=BE12, $G12=BF12), 1, 0)))) -> 0 | BH12: =IF(OR(BE12="", BF12="", $E12="", $G12=""), 0, IF(AND($E12=BE12, $G12=BF12), 1, 0)) -> 0 | BK12: =IF(OR(BI12="", BJ12=""), 0, IF(OR($E12="", $G12=""), "", (IF(SIGN($E12-$G12)=SIGN(BI12-BJ12), 2, 0) + IF($E12=BI12, 1, 0) + IF($G12=BJ12, 1, 0) + IF(AND($E12=BI12, $G12=BJ12), 1, 0)))) -> 0 | BL12: =IF(OR(BI12="", BJ12="", $E12="", $G12=""), 0, IF(AND($E12=BI12, $G12=BJ12), 1, 0)) -> 0
A13: =CALENDARIO!A13 -> 12 | B13: =CALENDARIO!B13 -> 46187 | C13: =CALENDARIO!C13 -> 0.95833333 | D13: =CALENDARIO!D13 -> Suécia | E13: =CALENDARIO!E13 -> 0 | F13: =CALENDARIO!F13 -> x | G13: =CALENDARIO!G13 -> 0 | H13: =CALENDARIO!H13 -> Tunísia | K13: =IF(OR(I13="", J13=""), 0, IF(OR($E13="", $G13=""), "", (IF(SIGN($E13-$G13)=SIGN(I13-J13), 2, 0) + IF($E13=I13, 1, 0) + IF($G13=J13, 1, 0) + IF(AND($E13=I13, $G13=J13), 1, 0)))) -> 0 | L13: =IF(OR(I13="", J13="", $E13="", $G13=""), 0, IF(AND($E13=I13, $G13=J13), 1, 0)) -> 0 | O13: =IF(OR(M13="", N13=""), 0, IF(OR($E13="", $G13=""), "", (IF(SIGN($E13-$G13)=SIGN(M13-N13), 2, 0) + IF($E13=M13, 1, 0) + IF($G13=N13, 1, 0) + IF(AND($E13=M13, $G13=N13), 1, 0)))) -> 0 | P13: =IF(OR(M13="", N13="", $E13="", $G13=""), 0, IF(AND($E13=M13, $G13=N13), 1, 0)) -> 0 | S13: =IF(OR(Q13="", R13=""), 0, IF(OR($E13="", $G13=""), "", (IF(SIGN($E13-$G13)=SIGN(Q13-R13), 2, 0) + IF($E13=Q13, 1, 0) + IF($G13=R13, 1, 0) + IF(AND($E13=Q13, $G13=R13), 1, 0)))) -> 0 | T13: =IF(OR(Q13="", R13="", $E13="", $G13=""), 0, IF(AND($E13=Q13, $G13=R13), 1, 0)) -> 0 | W13: =IF(OR(U13="", V13=""), 0, IF(OR($E13="", $G13=""), "", (IF(SIGN($E13-$G13)=SIGN(U13-V13), 2, 0) + IF($E13=U13, 1, 0) + IF($G13=V13, 1, 0) + IF(AND($E13=U13, $G13=V13), 1, 0)))) -> 0 | X13: =IF(OR(U13="", V13="", $E13="", $G13=""), 0, IF(AND($E13=U13, $G13=V13), 1, 0)) -> 0 | AA13: =IF(OR(Y13="", Z13=""), 0, IF(OR($E13="", $G13=""), "", (IF(SIGN($E13-$G13)=SIGN(Y13-Z13), 2, 0) + IF($E13=Y13, 1, 0) + IF($G13=Z13, 1, 0) + IF(AND($E13=Y13, $G13=Z13), 1, 0)))) -> 0 | AB13: =IF(OR(Y13="", Z13="", $E13="", $G13=""), 0, IF(AND($E13=Y13, $G13=Z13), 1, 0)) -> 0 | AE13: =IF(OR(AC13="", AD13=""), 0, IF(OR($E13="", $G13=""), "", (IF(SIGN($E13-$G13)=SIGN(AC13-AD13), 2, 0) + IF($E13=AC13, 1, 0) + IF($G13=AD13, 1, 0) + IF(AND($E13=AC13, $G13=AD13), 1, 0)))) -> 0 | AF13: =IF(OR(AC13="", AD13="", $E13="", $G13=""), 0, IF(AND($E13=AC13, $G13=AD13), 1, 0)) -> 0 | AI13: =IF(OR(AG13="", AH13=""), 0, IF(OR($E13="", $G13=""), "", (IF(SIGN($E13-$G13)=SIGN(AG13-AH13), 2, 0) + IF($E13=AG13, 1, 0) + IF($G13=AH13, 1, 0) + IF(AND($E13=AG13, $G13=AH13), 1, 0)))) -> 0 | AJ13: =IF(OR(AG13="", AH13="", $E13="", $G13=""), 0, IF(AND($E13=AG13, $G13=AH13), 1, 0)) -> 0 | AM13: =IF(OR(AK13="", AL13=""), 0, IF(OR($E13="", $G13=""), "", (IF(SIGN($E13-$G13)=SIGN(AK13-AL13), 2, 0) + IF($E13=AK13, 1, 0) + IF($G13=AL13, 1, 0) + IF(AND($E13=AK13, $G13=AL13), 1, 0)))) -> 0 | AN13: =IF(OR(AK13="", AL13="", $E13="", $G13=""), 0, IF(AND($E13=AK13, $G13=AL13), 1, 0)) -> 0 | AQ13: =IF(OR(AO13="", AP13=""), 0, IF(OR($E13="", $G13=""), "", (IF(SIGN($E13-$G13)=SIGN(AO13-AP13), 2, 0) + IF($E13=AO13, 1, 0) + IF($G13=AP13, 1, 0) + IF(AND($E13=AO13, $G13=AP13), 1, 0)))) -> 0 | AR13: =IF(OR(AO13="", AP13="", $E13="", $G13=""), 0, IF(AND($E13=AO13, $G13=AP13), 1, 0)) -> 0 | AU13: =IF(OR(AS13="", AT13=""), 0, IF(OR($E13="", $G13=""), "", (IF(SIGN($E13-$G13)=SIGN(AS13-AT13), 2, 0) + IF($E13=AS13, 1, 0) + IF($G13=AT13, 1, 0) + IF(AND($E13=AS13, $G13=AT13), 1, 0)))) -> 0 | AV13: =IF(OR(AS13="", AT13="", $E13="", $G13=""), 0, IF(AND($E13=AS13, $G13=AT13), 1, 0)) -> 0 | AY13: =IF(OR(AW13="", AX13=""), 0, IF(OR($E13="", $G13=""), "", (IF(SIGN($E13-$G13)=SIGN(AW13-AX13), 2, 0) + IF($E13=AW13, 1, 0) + IF($G13=AX13, 1, 0) + IF(AND($E13=AW13, $G13=AX13), 1, 0)))) -> 0 | AZ13: =IF(OR(AW13="", AX13="", $E13="", $G13=""), 0, IF(AND($E13=AW13, $G13=AX13), 1, 0)) -> 0 | BC13: =IF(OR(BA13="", BB13=""), 0, IF(OR($E13="", $G13=""), "", (IF(SIGN($E13-$G13)=SIGN(BA13-BB13), 2, 0) + IF($E13=BA13, 1, 0) + IF($G13=BB13, 1, 0) + IF(AND($E13=BA13, $G13=BB13), 1, 0)))) -> 0 | BD13: =IF(OR(BA13="", BB13="", $E13="", $G13=""), 0, IF(AND($E13=BA13, $G13=BB13), 1, 0)) -> 0 | BG13: =IF(OR(BE13="", BF13=""), 0, IF(OR($E13="", $G13=""), "", (IF(SIGN($E13-$G13)=SIGN(BE13-BF13), 2, 0) + IF($E13=BE13, 1, 0) + IF($G13=BF13, 1, 0) + IF(AND($E13=BE13, $G13=BF13), 1, 0)))) -> 0 | BH13: =IF(OR(BE13="", BF13="", $E13="", $G13=""), 0, IF(AND($E13=BE13, $G13=BF13), 1, 0)) -> 0 | BK13: =IF(OR(BI13="", BJ13=""), 0, IF(OR($E13="", $G13=""), "", (IF(SIGN($E13-$G13)=SIGN(BI13-BJ13), 2, 0) + IF($E13=BI13, 1, 0) + IF($G13=BJ13, 1, 0) + IF(AND($E13=BI13, $G13=BJ13), 1, 0)))) -> 0 | BL13: =IF(OR(BI13="", BJ13="", $E13="", $G13=""), 0, IF(AND($E13=BI13, $G13=BJ13), 1, 0)) -> 0
